30/05/23 (20:49:57) | ERROR: Exception while getting cpu frequency!
30/05/23 (20:49:57) | ERROR: [Errno 2] No such file or directory (originated from sysctl(HW_CPU_FREQ))
Traceback (most recent call last):
  File "/opt/local/bin/bpytop", line 3080, in _collect
    if CONFIG.show_cpu_freq and hasattr(psutil.cpu_freq(), "current"):
  File "/opt/local/Library/Frameworks/Python.framework/Versions/3.9/lib/python3.9/site-packages/psutil/__init__.py", line 1869, in cpu_freq
    ret = _psplatform.cpu_freq()
  File "/opt/local/Library/Frameworks/Python.framework/Versions/3.9/lib/python3.9/site-packages/psutil/_psosx.py", line 179, in cpu_freq
    curr, min_, max_ = cext.cpu_freq()
FileNotFoundError: [Errno 2] No such file or directory (originated from sysctl(HW_CPU_FREQ))
30/05/23 (20:51:10) | ERROR: Exception while getting cpu frequency!
30/05/23 (20:51:10) | ERROR: [Errno 2] No such file or directory (originated from sysctl(HW_CPU_FREQ))
Traceback (most recent call last):
  File "/opt/local/bin/bpytop", line 3080, in _collect
    if CONFIG.show_cpu_freq and hasattr(psutil.cpu_freq(), "current"):
  File "/opt/local/Library/Frameworks/Python.framework/Versions/3.9/lib/python3.9/site-packages/psutil/__init__.py", line 1869, in cpu_freq
    ret = _psplatform.cpu_freq()
  File "/opt/local/Library/Frameworks/Python.framework/Versions/3.9/lib/python3.9/site-packages/psutil/_psosx.py", line 179, in cpu_freq
    curr, min_, max_ = cext.cpu_freq()
FileNotFoundError: [Errno 2] No such file or directory (originated from sysctl(HW_CPU_FREQ))
01/06/23 (12:47:36) | ERROR: Exception while getting cpu frequency!
01/06/23 (12:47:36) | ERROR: [Errno 2] No such file or directory (originated from sysctl(HW_CPU_FREQ))
Traceback (most recent call last):
  File "/opt/local/bin/bpytop", line 3080, in _collect
    if CONFIG.show_cpu_freq and hasattr(psutil.cpu_freq(), "current"):
  File "/opt/local/Library/Frameworks/Python.framework/Versions/3.9/lib/python3.9/site-packages/psutil/__init__.py", line 1869, in cpu_freq
    ret = _psplatform.cpu_freq()
  File "/opt/local/Library/Frameworks/Python.framework/Versions/3.9/lib/python3.9/site-packages/psutil/_psosx.py", line 179, in cpu_freq
    curr, min_, max_ = cext.cpu_freq()
FileNotFoundError: [Errno 2] No such file or directory (originated from sysctl(HW_CPU_FREQ))
01/06/23 (12:51:21) | ERROR: Exception while getting cpu frequency!
01/06/23 (12:51:21) | ERROR: [Errno 2] No such file or directory (originated from sysctl(HW_CPU_FREQ))
Traceback (most recent call last):
  File "/opt/local/bin/bpytop", line 3080, in _collect
    if CONFIG.show_cpu_freq and hasattr(psutil.cpu_freq(), "current"):
  File "/opt/local/Library/Frameworks/Python.framework/Versions/3.9/lib/python3.9/site-packages/psutil/__init__.py", line 1869, in cpu_freq
    ret = _psplatform.cpu_freq()
  File "/opt/local/Library/Frameworks/Python.framework/Versions/3.9/lib/python3.9/site-packages/psutil/_psosx.py", line 179, in cpu_freq
    curr, min_, max_ = cext.cpu_freq()
FileNotFoundError: [Errno 2] No such file or directory (originated from sysctl(HW_CPU_FREQ))
06/06/23 (11:15:55) | ERROR: Exception while getting cpu frequency!
06/06/23 (11:15:55) | ERROR: [Errno 2] No such file or directory (originated from sysctl(HW_CPU_FREQ))
Traceback (most recent call last):
  File "/opt/local/bin/bpytop", line 3080, in _collect
    if CONFIG.show_cpu_freq and hasattr(psutil.cpu_freq(), "current"):
  File "/opt/local/Library/Frameworks/Python.framework/Versions/3.9/lib/python3.9/site-packages/psutil/__init__.py", line 1869, in cpu_freq
    ret = _psplatform.cpu_freq()
  File "/opt/local/Library/Frameworks/Python.framework/Versions/3.9/lib/python3.9/site-packages/psutil/_psosx.py", line 179, in cpu_freq
    curr, min_, max_ = cext.cpu_freq()
FileNotFoundError: [Errno 2] No such file or directory (originated from sysctl(HW_CPU_FREQ))
10/06/23 (22:47:28) | ERROR: Exception while getting cpu frequency!
10/06/23 (22:47:28) | ERROR: [Errno 2] No such file or directory (originated from sysctl(HW_CPU_FREQ))
Traceback (most recent call last):
  File "/opt/local/bin/bpytop", line 3080, in _collect
    if CONFIG.show_cpu_freq and hasattr(psutil.cpu_freq(), "current"):
  File "/opt/local/Library/Frameworks/Python.framework/Versions/3.9/lib/python3.9/site-packages/psutil/__init__.py", line 1869, in cpu_freq
    ret = _psplatform.cpu_freq()
  File "/opt/local/Library/Frameworks/Python.framework/Versions/3.9/lib/python3.9/site-packages/psutil/_psosx.py", line 179, in cpu_freq
    curr, min_, max_ = cext.cpu_freq()
FileNotFoundError: [Errno 2] No such file or directory (originated from sysctl(HW_CPU_FREQ))
12/06/23 (14:15:26) | ERROR: Exception while getting cpu frequency!
12/06/23 (14:15:26) | ERROR: [Errno 2] No such file or directory (originated from sysctl(HW_CPU_FREQ))
Traceback (most recent call last):
  File "/opt/local/bin/bpytop", line 3080, in _collect
    if CONFIG.show_cpu_freq and hasattr(psutil.cpu_freq(), "current"):
  File "/opt/local/Library/Frameworks/Python.framework/Versions/3.9/lib/python3.9/site-packages/psutil/__init__.py", line 1869, in cpu_freq
    ret = _psplatform.cpu_freq()
  File "/opt/local/Library/Frameworks/Python.framework/Versions/3.9/lib/python3.9/site-packages/psutil/_psosx.py", line 179, in cpu_freq
    curr, min_, max_ = cext.cpu_freq()
FileNotFoundError: [Errno 2] No such file or directory (originated from sysctl(HW_CPU_FREQ))
29/06/23 (11:52:32) | ERROR: <urlopen error [Errno 8] nodename nor servname provided, or not known>
Traceback (most recent call last):
  File "/opt/local/Library/Frameworks/Python.framework/Versions/3.9/lib/python3.9/urllib/request.py", line 1346, in do_open
    h.request(req.get_method(), req.selector, req.data, headers,
  File "/opt/local/Library/Frameworks/Python.framework/Versions/3.9/lib/python3.9/http/client.py", line 1285, in request
    self._send_request(method, url, body, headers, encode_chunked)
  File "/opt/local/Library/Frameworks/Python.framework/Versions/3.9/lib/python3.9/http/client.py", line 1331, in _send_request
    self.endheaders(body, encode_chunked=encode_chunked)
  File "/opt/local/Library/Frameworks/Python.framework/Versions/3.9/lib/python3.9/http/client.py", line 1280, in endheaders
    self._send_output(message_body, encode_chunked=encode_chunked)
  File "/opt/local/Library/Frameworks/Python.framework/Versions/3.9/lib/python3.9/http/client.py", line 1040, in _send_output
    self.send(msg)
  File "/opt/local/Library/Frameworks/Python.framework/Versions/3.9/lib/python3.9/http/client.py", line 980, in send
    self.connect()
  File "/opt/local/Library/Frameworks/Python.framework/Versions/3.9/lib/python3.9/http/client.py", line 1447, in connect
    super().connect()
  File "/opt/local/Library/Frameworks/Python.framework/Versions/3.9/lib/python3.9/http/client.py", line 946, in connect
    self.sock = self._create_connection(
  File "/opt/local/Library/Frameworks/Python.framework/Versions/3.9/lib/python3.9/socket.py", line 823, in create_connection
    for res in getaddrinfo(host, port, 0, SOCK_STREAM):
  File "/opt/local/Library/Frameworks/Python.framework/Versions/3.9/lib/python3.9/socket.py", line 954, in getaddrinfo
    for res in _socket.getaddrinfo(host, port, family, type, proto, flags):
socket.gaierror: [Errno 8] nodename nor servname provided, or not known

During handling of the above exception, another exception occurred:

Traceback (most recent call last):
  File "/opt/local/bin/bpytop", line 5029, in _checker
    with urllib.request.urlopen("https://github.com/aristocratos/bpytop/raw/master/bpytop.py", timeout=5) as source: # type: ignore
  File "/opt/local/Library/Frameworks/Python.framework/Versions/3.9/lib/python3.9/urllib/request.py", line 214, in urlopen
    return opener.open(url, data, timeout)
  File "/opt/local/Library/Frameworks/Python.framework/Versions/3.9/lib/python3.9/urllib/request.py", line 517, in open
    response = self._open(req, data)
  File "/opt/local/Library/Frameworks/Python.framework/Versions/3.9/lib/python3.9/urllib/request.py", line 534, in _open
    result = self._call_chain(self.handle_open, protocol, protocol +
  File "/opt/local/Library/Frameworks/Python.framework/Versions/3.9/lib/python3.9/urllib/request.py", line 494, in _call_chain
    result = func(*args)
  File "/opt/local/Library/Frameworks/Python.framework/Versions/3.9/lib/python3.9/urllib/request.py", line 1389, in https_open
    return self.do_open(http.client.HTTPSConnection, req,
  File "/opt/local/Library/Frameworks/Python.framework/Versions/3.9/lib/python3.9/urllib/request.py", line 1349, in do_open
    raise URLError(err)
urllib.error.URLError: <urlopen error [Errno 8] nodename nor servname provided, or not known>
29/06/23 (11:52:33) | ERROR: Exception while getting cpu frequency!
29/06/23 (11:52:33) | ERROR: [Errno 2] No such file or directory (originated from sysctl(HW_CPU_FREQ))
Traceback (most recent call last):
  File "/opt/local/bin/bpytop", line 3080, in _collect
    if CONFIG.show_cpu_freq and hasattr(psutil.cpu_freq(), "current"):
  File "/opt/local/Library/Frameworks/Python.framework/Versions/3.9/lib/python3.9/site-packages/psutil/__init__.py", line 1869, in cpu_freq
    ret = _psplatform.cpu_freq()
  File "/opt/local/Library/Frameworks/Python.framework/Versions/3.9/lib/python3.9/site-packages/psutil/_psosx.py", line 179, in cpu_freq
    curr, min_, max_ = cext.cpu_freq()
FileNotFoundError: [Errno 2] No such file or directory (originated from sysctl(HW_CPU_FREQ))
30/06/23 (14:06:48) | ERROR: <urlopen error [Errno 8] nodename nor servname provided, or not known>
Traceback (most recent call last):
  File "/opt/local/Library/Frameworks/Python.framework/Versions/3.9/lib/python3.9/urllib/request.py", line 1346, in do_open
    h.request(req.get_method(), req.selector, req.data, headers,
  File "/opt/local/Library/Frameworks/Python.framework/Versions/3.9/lib/python3.9/http/client.py", line 1285, in request
    self._send_request(method, url, body, headers, encode_chunked)
  File "/opt/local/Library/Frameworks/Python.framework/Versions/3.9/lib/python3.9/http/client.py", line 1331, in _send_request
    self.endheaders(body, encode_chunked=encode_chunked)
  File "/opt/local/Library/Frameworks/Python.framework/Versions/3.9/lib/python3.9/http/client.py", line 1280, in endheaders
    self._send_output(message_body, encode_chunked=encode_chunked)
  File "/opt/local/Library/Frameworks/Python.framework/Versions/3.9/lib/python3.9/http/client.py", line 1040, in _send_output
    self.send(msg)
  File "/opt/local/Library/Frameworks/Python.framework/Versions/3.9/lib/python3.9/http/client.py", line 980, in send
    self.connect()
  File "/opt/local/Library/Frameworks/Python.framework/Versions/3.9/lib/python3.9/http/client.py", line 1447, in connect
    super().connect()
  File "/opt/local/Library/Frameworks/Python.framework/Versions/3.9/lib/python3.9/http/client.py", line 946, in connect
    self.sock = self._create_connection(
  File "/opt/local/Library/Frameworks/Python.framework/Versions/3.9/lib/python3.9/socket.py", line 823, in create_connection
    for res in getaddrinfo(host, port, 0, SOCK_STREAM):
  File "/opt/local/Library/Frameworks/Python.framework/Versions/3.9/lib/python3.9/socket.py", line 954, in getaddrinfo
    for res in _socket.getaddrinfo(host, port, family, type, proto, flags):
socket.gaierror: [Errno 8] nodename nor servname provided, or not known

During handling of the above exception, another exception occurred:

Traceback (most recent call last):
  File "/opt/local/bin/bpytop", line 5029, in _checker
    with urllib.request.urlopen("https://github.com/aristocratos/bpytop/raw/master/bpytop.py", timeout=5) as source: # type: ignore
  File "/opt/local/Library/Frameworks/Python.framework/Versions/3.9/lib/python3.9/urllib/request.py", line 214, in urlopen
    return opener.open(url, data, timeout)
  File "/opt/local/Library/Frameworks/Python.framework/Versions/3.9/lib/python3.9/urllib/request.py", line 517, in open
    response = self._open(req, data)
  File "/opt/local/Library/Frameworks/Python.framework/Versions/3.9/lib/python3.9/urllib/request.py", line 534, in _open
    result = self._call_chain(self.handle_open, protocol, protocol +
  File "/opt/local/Library/Frameworks/Python.framework/Versions/3.9/lib/python3.9/urllib/request.py", line 494, in _call_chain
    result = func(*args)
  File "/opt/local/Library/Frameworks/Python.framework/Versions/3.9/lib/python3.9/urllib/request.py", line 1389, in https_open
    return self.do_open(http.client.HTTPSConnection, req,
  File "/opt/local/Library/Frameworks/Python.framework/Versions/3.9/lib/python3.9/urllib/request.py", line 1349, in do_open
    raise URLError(err)
urllib.error.URLError: <urlopen error [Errno 8] nodename nor servname provided, or not known>
30/06/23 (14:06:48) | ERROR: Exception while getting cpu frequency!
30/06/23 (14:06:48) | ERROR: [Errno 2] No such file or directory (originated from sysctl(HW_CPU_FREQ))
Traceback (most recent call last):
  File "/opt/local/bin/bpytop", line 3080, in _collect
    if CONFIG.show_cpu_freq and hasattr(psutil.cpu_freq(), "current"):
  File "/opt/local/Library/Frameworks/Python.framework/Versions/3.9/lib/python3.9/site-packages/psutil/__init__.py", line 1869, in cpu_freq
    ret = _psplatform.cpu_freq()
  File "/opt/local/Library/Frameworks/Python.framework/Versions/3.9/lib/python3.9/site-packages/psutil/_psosx.py", line 179, in cpu_freq
    curr, min_, max_ = cext.cpu_freq()
FileNotFoundError: [Errno 2] No such file or directory (originated from sysctl(HW_CPU_FREQ))
06/07/23 (23:22:52) | ERROR: Exception while getting cpu frequency!
06/07/23 (23:22:52) | ERROR: [Errno 2] No such file or directory (originated from sysctl(HW_CPU_FREQ))
Traceback (most recent call last):
  File "/opt/local/bin/bpytop", line 3080, in _collect
    if CONFIG.show_cpu_freq and hasattr(psutil.cpu_freq(), "current"):
  File "/opt/local/Library/Frameworks/Python.framework/Versions/3.9/lib/python3.9/site-packages/psutil/__init__.py", line 1869, in cpu_freq
    ret = _psplatform.cpu_freq()
  File "/opt/local/Library/Frameworks/Python.framework/Versions/3.9/lib/python3.9/site-packages/psutil/_psosx.py", line 179, in cpu_freq
    curr, min_, max_ = cext.cpu_freq()
FileNotFoundError: [Errno 2] No such file or directory (originated from sysctl(HW_CPU_FREQ))
10/07/23 (21:30:13) | ERROR: Exception while getting cpu frequency!
10/07/23 (21:30:13) | ERROR: [Errno 2] No such file or directory (originated from sysctl(HW_CPU_FREQ))
Traceback (most recent call last):
  File "/opt/local/bin/bpytop", line 3080, in _collect
    if CONFIG.show_cpu_freq and hasattr(psutil.cpu_freq(), "current"):
  File "/opt/local/Library/Frameworks/Python.framework/Versions/3.9/lib/python3.9/site-packages/psutil/__init__.py", line 1869, in cpu_freq
    ret = _psplatform.cpu_freq()
  File "/opt/local/Library/Frameworks/Python.framework/Versions/3.9/lib/python3.9/site-packages/psutil/_psosx.py", line 179, in cpu_freq
    curr, min_, max_ = cext.cpu_freq()
FileNotFoundError: [Errno 2] No such file or directory (originated from sysctl(HW_CPU_FREQ))
10/07/23 (21:30:19) | ERROR: <urlopen error timed out>
Traceback (most recent call last):
  File "/opt/local/Library/Frameworks/Python.framework/Versions/3.9/lib/python3.9/urllib/request.py", line 1346, in do_open
    h.request(req.get_method(), req.selector, req.data, headers,
  File "/opt/local/Library/Frameworks/Python.framework/Versions/3.9/lib/python3.9/http/client.py", line 1285, in request
    self._send_request(method, url, body, headers, encode_chunked)
  File "/opt/local/Library/Frameworks/Python.framework/Versions/3.9/lib/python3.9/http/client.py", line 1331, in _send_request
    self.endheaders(body, encode_chunked=encode_chunked)
  File "/opt/local/Library/Frameworks/Python.framework/Versions/3.9/lib/python3.9/http/client.py", line 1280, in endheaders
    self._send_output(message_body, encode_chunked=encode_chunked)
  File "/opt/local/Library/Frameworks/Python.framework/Versions/3.9/lib/python3.9/http/client.py", line 1040, in _send_output
    self.send(msg)
  File "/opt/local/Library/Frameworks/Python.framework/Versions/3.9/lib/python3.9/http/client.py", line 980, in send
    self.connect()
  File "/opt/local/Library/Frameworks/Python.framework/Versions/3.9/lib/python3.9/http/client.py", line 1447, in connect
    super().connect()
  File "/opt/local/Library/Frameworks/Python.framework/Versions/3.9/lib/python3.9/http/client.py", line 946, in connect
    self.sock = self._create_connection(
  File "/opt/local/Library/Frameworks/Python.framework/Versions/3.9/lib/python3.9/socket.py", line 844, in create_connection
    raise err
  File "/opt/local/Library/Frameworks/Python.framework/Versions/3.9/lib/python3.9/socket.py", line 832, in create_connection
    sock.connect(sa)
socket.timeout: timed out

During handling of the above exception, another exception occurred:

Traceback (most recent call last):
  File "/opt/local/bin/bpytop", line 5029, in _checker
    with urllib.request.urlopen("https://github.com/aristocratos/bpytop/raw/master/bpytop.py", timeout=5) as source: # type: ignore
  File "/opt/local/Library/Frameworks/Python.framework/Versions/3.9/lib/python3.9/urllib/request.py", line 214, in urlopen
    return opener.open(url, data, timeout)
  File "/opt/local/Library/Frameworks/Python.framework/Versions/3.9/lib/python3.9/urllib/request.py", line 517, in open
    response = self._open(req, data)
  File "/opt/local/Library/Frameworks/Python.framework/Versions/3.9/lib/python3.9/urllib/request.py", line 534, in _open
    result = self._call_chain(self.handle_open, protocol, protocol +
  File "/opt/local/Library/Frameworks/Python.framework/Versions/3.9/lib/python3.9/urllib/request.py", line 494, in _call_chain
    result = func(*args)
  File "/opt/local/Library/Frameworks/Python.framework/Versions/3.9/lib/python3.9/urllib/request.py", line 1389, in https_open
    return self.do_open(http.client.HTTPSConnection, req,
  File "/opt/local/Library/Frameworks/Python.framework/Versions/3.9/lib/python3.9/urllib/request.py", line 1349, in do_open
    raise URLError(err)
urllib.error.URLError: <urlopen error timed out>
10/09/23 (13:54:10) | ERROR: Exception while getting cpu frequency!
10/09/23 (13:54:10) | ERROR: [Errno 2] No such file or directory (originated from sysctl(HW_CPU_FREQ))
Traceback (most recent call last):
  File "/opt/local/bin/bpytop", line 3080, in _collect
    if CONFIG.show_cpu_freq and hasattr(psutil.cpu_freq(), "current"):
  File "/opt/local/Library/Frameworks/Python.framework/Versions/3.9/lib/python3.9/site-packages/psutil/__init__.py", line 1869, in cpu_freq
    ret = _psplatform.cpu_freq()
  File "/opt/local/Library/Frameworks/Python.framework/Versions/3.9/lib/python3.9/site-packages/psutil/_psosx.py", line 179, in cpu_freq
    curr, min_, max_ = cext.cpu_freq()
FileNotFoundError: [Errno 2] No such file or directory (originated from sysctl(HW_CPU_FREQ))
10/09/23 (13:59:02) | ERROR: Exception while getting cpu frequency!
10/09/23 (13:59:02) | ERROR: [Errno 2] No such file or directory (originated from sysctl(HW_CPU_FREQ))
Traceback (most recent call last):
  File "/opt/local/bin/bpytop", line 3080, in _collect
    if CONFIG.show_cpu_freq and hasattr(psutil.cpu_freq(), "current"):
  File "/opt/local/Library/Frameworks/Python.framework/Versions/3.9/lib/python3.9/site-packages/psutil/__init__.py", line 1869, in cpu_freq
    ret = _psplatform.cpu_freq()
  File "/opt/local/Library/Frameworks/Python.framework/Versions/3.9/lib/python3.9/site-packages/psutil/_psosx.py", line 179, in cpu_freq
    curr, min_, max_ = cext.cpu_freq()
FileNotFoundError: [Errno 2] No such file or directory (originated from sysctl(HW_CPU_FREQ))
10/09/23 (14:01:10) | ERROR: Exception while getting cpu frequency!
10/09/23 (14:01:10) | ERROR: [Errno 2] No such file or directory (originated from sysctl(HW_CPU_FREQ))
Traceback (most recent call last):
  File "/opt/local/bin/bpytop", line 3080, in _collect
    if CONFIG.show_cpu_freq and hasattr(psutil.cpu_freq(), "current"):
  File "/opt/local/Library/Frameworks/Python.framework/Versions/3.9/lib/python3.9/site-packages/psutil/__init__.py", line 1869, in cpu_freq
    ret = _psplatform.cpu_freq()
  File "/opt/local/Library/Frameworks/Python.framework/Versions/3.9/lib/python3.9/site-packages/psutil/_psosx.py", line 179, in cpu_freq
    curr, min_, max_ = cext.cpu_freq()
FileNotFoundError: [Errno 2] No such file or directory (originated from sysctl(HW_CPU_FREQ))
10/09/23 (14:01:45) | ERROR: Exception while getting cpu frequency!
10/09/23 (14:01:45) | ERROR: [Errno 2] No such file or directory (originated from sysctl(HW_CPU_FREQ))
Traceback (most recent call last):
  File "/opt/local/bin/bpytop", line 3080, in _collect
    if CONFIG.show_cpu_freq and hasattr(psutil.cpu_freq(), "current"):
  File "/opt/local/Library/Frameworks/Python.framework/Versions/3.9/lib/python3.9/site-packages/psutil/__init__.py", line 1869, in cpu_freq
    ret = _psplatform.cpu_freq()
  File "/opt/local/Library/Frameworks/Python.framework/Versions/3.9/lib/python3.9/site-packages/psutil/_psosx.py", line 179, in cpu_freq
    curr, min_, max_ = cext.cpu_freq()
FileNotFoundError: [Errno 2] No such file or directory (originated from sysctl(HW_CPU_FREQ))
10/09/23 (14:02:40) | ERROR: Exception while getting cpu frequency!
10/09/23 (14:02:40) | ERROR: [Errno 2] No such file or directory (originated from sysctl(HW_CPU_FREQ))
Traceback (most recent call last):
  File "/opt/local/bin/bpytop", line 3080, in _collect
    if CONFIG.show_cpu_freq and hasattr(psutil.cpu_freq(), "current"):
  File "/opt/local/Library/Frameworks/Python.framework/Versions/3.9/lib/python3.9/site-packages/psutil/__init__.py", line 1869, in cpu_freq
    ret = _psplatform.cpu_freq()
  File "/opt/local/Library/Frameworks/Python.framework/Versions/3.9/lib/python3.9/site-packages/psutil/_psosx.py", line 179, in cpu_freq
    curr, min_, max_ = cext.cpu_freq()
FileNotFoundError: [Errno 2] No such file or directory (originated from sysctl(HW_CPU_FREQ))
10/09/23 (14:02:59) | ERROR: Data collection thread failed with exception: [Errno 5] Input/output error
Traceback (most recent call last):
  File "/opt/local/bin/bpytop", line 2965, in _runner
    else: Draw.out()
  File "/opt/local/bin/bpytop", line 1091, in out
    cls.now(out)
  File "/opt/local/bin/bpytop", line 1039, in now
    print(*args, sep="", end="", flush=True)
OSError: [Errno 5] Input/output error
10/09/23 (14:03:45) | ERROR: Exception while getting cpu frequency!
10/09/23 (14:03:45) | ERROR: [Errno 2] No such file or directory (originated from sysctl(HW_CPU_FREQ))
Traceback (most recent call last):
  File "/opt/local/bin/bpytop", line 3080, in _collect
    if CONFIG.show_cpu_freq and hasattr(psutil.cpu_freq(), "current"):
  File "/opt/local/Library/Frameworks/Python.framework/Versions/3.9/lib/python3.9/site-packages/psutil/__init__.py", line 1869, in cpu_freq
    ret = _psplatform.cpu_freq()
  File "/opt/local/Library/Frameworks/Python.framework/Versions/3.9/lib/python3.9/site-packages/psutil/_psosx.py", line 179, in cpu_freq
    curr, min_, max_ = cext.cpu_freq()
FileNotFoundError: [Errno 2] No such file or directory (originated from sysctl(HW_CPU_FREQ))
10/09/23 (14:04:30) | ERROR: Exception while getting cpu frequency!
10/09/23 (14:04:30) | ERROR: [Errno 2] No such file or directory (originated from sysctl(HW_CPU_FREQ))
Traceback (most recent call last):
  File "/opt/local/bin/bpytop", line 3080, in _collect
    if CONFIG.show_cpu_freq and hasattr(psutil.cpu_freq(), "current"):
  File "/opt/local/Library/Frameworks/Python.framework/Versions/3.9/lib/python3.9/site-packages/psutil/__init__.py", line 1869, in cpu_freq
    ret = _psplatform.cpu_freq()
  File "/opt/local/Library/Frameworks/Python.framework/Versions/3.9/lib/python3.9/site-packages/psutil/_psosx.py", line 179, in cpu_freq
    curr, min_, max_ = cext.cpu_freq()
FileNotFoundError: [Errno 2] No such file or directory (originated from sysctl(HW_CPU_FREQ))
10/09/23 (14:04:45) | ERROR: [Errno 5] Input/output error
Traceback (most recent call last):
  File "/opt/local/bin/bpytop", line 5677, in main
    run()
  File "/opt/local/bin/bpytop", line 5671, in run
    process_keys()
  File "/opt/local/bin/bpytop", line 5422, in process_keys
    Menu.main()
  File "/opt/local/bin/bpytop", line 4096, in main
    cls.options()
  File "/opt/local/bin/bpytop", line 4736, in options
    Draw.now(f'{cls.background}{out_misc}{out}')
  File "/opt/local/bin/bpytop", line 1039, in now
    print(*args, sep="", end="", flush=True)
OSError: [Errno 5] Input/output error
10/09/23 (14:05:23) | WARNING: No theme named "monokai" found!
10/09/23 (14:05:23) | ERROR: Exception while getting cpu frequency!
10/09/23 (14:05:23) | ERROR: [Errno 2] No such file or directory (originated from sysctl(HW_CPU_FREQ))
Traceback (most recent call last):
  File "/opt/local/bin/bpytop", line 3080, in _collect
    if CONFIG.show_cpu_freq and hasattr(psutil.cpu_freq(), "current"):
  File "/opt/local/Library/Frameworks/Python.framework/Versions/3.9/lib/python3.9/site-packages/psutil/__init__.py", line 1869, in cpu_freq
    ret = _psplatform.cpu_freq()
  File "/opt/local/Library/Frameworks/Python.framework/Versions/3.9/lib/python3.9/site-packages/psutil/_psosx.py", line 179, in cpu_freq
    curr, min_, max_ = cext.cpu_freq()
FileNotFoundError: [Errno 2] No such file or directory (originated from sysctl(HW_CPU_FREQ))
10/09/23 (14:05:52) | ERROR: Exception while getting cpu frequency!
10/09/23 (14:05:52) | ERROR: [Errno 2] No such file or directory (originated from sysctl(HW_CPU_FREQ))
Traceback (most recent call last):
  File "/opt/local/bin/bpytop", line 3080, in _collect
    if CONFIG.show_cpu_freq and hasattr(psutil.cpu_freq(), "current"):
  File "/opt/local/Library/Frameworks/Python.framework/Versions/3.9/lib/python3.9/site-packages/psutil/__init__.py", line 1869, in cpu_freq
    ret = _psplatform.cpu_freq()
  File "/opt/local/Library/Frameworks/Python.framework/Versions/3.9/lib/python3.9/site-packages/psutil/_psosx.py", line 179, in cpu_freq
    curr, min_, max_ = cext.cpu_freq()
FileNotFoundError: [Errno 2] No such file or directory (originated from sysctl(HW_CPU_FREQ))
10/09/23 (14:06:45) | ERROR: Exception while getting cpu frequency!
10/09/23 (14:06:45) | ERROR: [Errno 2] No such file or directory (originated from sysctl(HW_CPU_FREQ))
Traceback (most recent call last):
  File "/opt/local/bin/bpytop", line 3080, in _collect
    if CONFIG.show_cpu_freq and hasattr(psutil.cpu_freq(), "current"):
  File "/opt/local/Library/Frameworks/Python.framework/Versions/3.9/lib/python3.9/site-packages/psutil/__init__.py", line 1869, in cpu_freq
    ret = _psplatform.cpu_freq()
  File "/opt/local/Library/Frameworks/Python.framework/Versions/3.9/lib/python3.9/site-packages/psutil/_psosx.py", line 179, in cpu_freq
    curr, min_, max_ = cext.cpu_freq()
FileNotFoundError: [Errno 2] No such file or directory (originated from sysctl(HW_CPU_FREQ))
22/09/23 (14:37:23) | ERROR: Exception while getting cpu frequency!
22/09/23 (14:37:23) | ERROR: [Errno 2] No such file or directory (originated from sysctl(HW_CPU_FREQ))
Traceback (most recent call last):
  File "/opt/local/bin/bpytop", line 3080, in _collect
    if CONFIG.show_cpu_freq and hasattr(psutil.cpu_freq(), "current"):
  File "/opt/local/Library/Frameworks/Python.framework/Versions/3.9/lib/python3.9/site-packages/psutil/__init__.py", line 1869, in cpu_freq
    ret = _psplatform.cpu_freq()
  File "/opt/local/Library/Frameworks/Python.framework/Versions/3.9/lib/python3.9/site-packages/psutil/_psosx.py", line 179, in cpu_freq
    curr, min_, max_ = cext.cpu_freq()
FileNotFoundError: [Errno 2] No such file or directory (originated from sysctl(HW_CPU_FREQ))
29/09/23 (09:59:54) | ERROR: Exception while getting cpu frequency!
29/09/23 (09:59:54) | ERROR: [Errno 2] No such file or directory (originated from sysctl(HW_CPU_FREQ))
Traceback (most recent call last):
  File "/opt/local/bin/bpytop", line 3080, in _collect
    if CONFIG.show_cpu_freq and hasattr(psutil.cpu_freq(), "current"):
  File "/opt/local/Library/Frameworks/Python.framework/Versions/3.9/lib/python3.9/site-packages/psutil/__init__.py", line 1869, in cpu_freq
    ret = _psplatform.cpu_freq()
  File "/opt/local/Library/Frameworks/Python.framework/Versions/3.9/lib/python3.9/site-packages/psutil/_psosx.py", line 179, in cpu_freq
    curr, min_, max_ = cext.cpu_freq()
FileNotFoundError: [Errno 2] No such file or directory (originated from sysctl(HW_CPU_FREQ))
29/09/23 (09:59:56) | ERROR: <urlopen error [SSL: CERTIFICATE_VERIFY_FAILED] certificate verify failed (_ssl.c:1129)>
Traceback (most recent call last):
  File "/opt/local/Library/Frameworks/Python.framework/Versions/3.9/lib/python3.9/urllib/request.py", line 1346, in do_open
    h.request(req.get_method(), req.selector, req.data, headers,
  File "/opt/local/Library/Frameworks/Python.framework/Versions/3.9/lib/python3.9/http/client.py", line 1285, in request
    self._send_request(method, url, body, headers, encode_chunked)
  File "/opt/local/Library/Frameworks/Python.framework/Versions/3.9/lib/python3.9/http/client.py", line 1331, in _send_request
    self.endheaders(body, encode_chunked=encode_chunked)
  File "/opt/local/Library/Frameworks/Python.framework/Versions/3.9/lib/python3.9/http/client.py", line 1280, in endheaders
    self._send_output(message_body, encode_chunked=encode_chunked)
  File "/opt/local/Library/Frameworks/Python.framework/Versions/3.9/lib/python3.9/http/client.py", line 1040, in _send_output
    self.send(msg)
  File "/opt/local/Library/Frameworks/Python.framework/Versions/3.9/lib/python3.9/http/client.py", line 980, in send
    self.connect()
  File "/opt/local/Library/Frameworks/Python.framework/Versions/3.9/lib/python3.9/http/client.py", line 1454, in connect
    self.sock = self._context.wrap_socket(self.sock,
  File "/opt/local/Library/Frameworks/Python.framework/Versions/3.9/lib/python3.9/ssl.py", line 501, in wrap_socket
    return self.sslsocket_class._create(
  File "/opt/local/Library/Frameworks/Python.framework/Versions/3.9/lib/python3.9/ssl.py", line 1074, in _create
    self.do_handshake()
  File "/opt/local/Library/Frameworks/Python.framework/Versions/3.9/lib/python3.9/ssl.py", line 1343, in do_handshake
    self._sslobj.do_handshake()
ssl.SSLError: [SSL: CERTIFICATE_VERIFY_FAILED] certificate verify failed (_ssl.c:1129)

During handling of the above exception, another exception occurred:

Traceback (most recent call last):
  File "/opt/local/bin/bpytop", line 5029, in _checker
    with urllib.request.urlopen("https://github.com/aristocratos/bpytop/raw/master/bpytop.py", timeout=5) as source: # type: ignore
  File "/opt/local/Library/Frameworks/Python.framework/Versions/3.9/lib/python3.9/urllib/request.py", line 214, in urlopen
    return opener.open(url, data, timeout)
  File "/opt/local/Library/Frameworks/Python.framework/Versions/3.9/lib/python3.9/urllib/request.py", line 517, in open
    response = self._open(req, data)
  File "/opt/local/Library/Frameworks/Python.framework/Versions/3.9/lib/python3.9/urllib/request.py", line 534, in _open
    result = self._call_chain(self.handle_open, protocol, protocol +
  File "/opt/local/Library/Frameworks/Python.framework/Versions/3.9/lib/python3.9/urllib/request.py", line 494, in _call_chain
    result = func(*args)
  File "/opt/local/Library/Frameworks/Python.framework/Versions/3.9/lib/python3.9/urllib/request.py", line 1389, in https_open
    return self.do_open(http.client.HTTPSConnection, req,
  File "/opt/local/Library/Frameworks/Python.framework/Versions/3.9/lib/python3.9/urllib/request.py", line 1349, in do_open
    raise URLError(err)
urllib.error.URLError: <urlopen error [SSL: CERTIFICATE_VERIFY_FAILED] certificate verify failed (_ssl.c:1129)>
03/10/23 (00:07:20) | ERROR: Exception while getting cpu frequency!
03/10/23 (00:07:20) | ERROR: [Errno 2] No such file or directory (originated from sysctl(HW_CPU_FREQ))
Traceback (most recent call last):
  File "/opt/local/bin/bpytop", line 3080, in _collect
    if CONFIG.show_cpu_freq and hasattr(psutil.cpu_freq(), "current"):
  File "/opt/local/Library/Frameworks/Python.framework/Versions/3.9/lib/python3.9/site-packages/psutil/__init__.py", line 1869, in cpu_freq
    ret = _psplatform.cpu_freq()
  File "/opt/local/Library/Frameworks/Python.framework/Versions/3.9/lib/python3.9/site-packages/psutil/_psosx.py", line 179, in cpu_freq
    curr, min_, max_ = cext.cpu_freq()
FileNotFoundError: [Errno 2] No such file or directory (originated from sysctl(HW_CPU_FREQ))
03/10/23 (00:10:44) | ERROR: Exception while getting cpu frequency!
03/10/23 (00:10:44) | ERROR: [Errno 2] No such file or directory (originated from sysctl(HW_CPU_FREQ))
Traceback (most recent call last):
  File "/opt/local/bin/bpytop", line 3080, in _collect
    if CONFIG.show_cpu_freq and hasattr(psutil.cpu_freq(), "current"):
  File "/opt/local/Library/Frameworks/Python.framework/Versions/3.9/lib/python3.9/site-packages/psutil/__init__.py", line 1869, in cpu_freq
    ret = _psplatform.cpu_freq()
  File "/opt/local/Library/Frameworks/Python.framework/Versions/3.9/lib/python3.9/site-packages/psutil/_psosx.py", line 179, in cpu_freq
    curr, min_, max_ = cext.cpu_freq()
FileNotFoundError: [Errno 2] No such file or directory (originated from sysctl(HW_CPU_FREQ))
03/10/23 (00:12:05) | ERROR: Exception while getting cpu frequency!
03/10/23 (00:12:05) | ERROR: [Errno 2] No such file or directory (originated from sysctl(HW_CPU_FREQ))
Traceback (most recent call last):
  File "/opt/local/bin/bpytop", line 3080, in _collect
    if CONFIG.show_cpu_freq and hasattr(psutil.cpu_freq(), "current"):
  File "/opt/local/Library/Frameworks/Python.framework/Versions/3.9/lib/python3.9/site-packages/psutil/__init__.py", line 1869, in cpu_freq
    ret = _psplatform.cpu_freq()
  File "/opt/local/Library/Frameworks/Python.framework/Versions/3.9/lib/python3.9/site-packages/psutil/_psosx.py", line 179, in cpu_freq
    curr, min_, max_ = cext.cpu_freq()
FileNotFoundError: [Errno 2] No such file or directory (originated from sysctl(HW_CPU_FREQ))
03/10/23 (19:29:13) | ERROR: Exception while getting cpu frequency!
03/10/23 (19:29:13) | ERROR: [Errno 2] No such file or directory (originated from sysctl(HW_CPU_FREQ))
Traceback (most recent call last):
  File "/opt/local/bin/bpytop", line 3080, in _collect
    if CONFIG.show_cpu_freq and hasattr(psutil.cpu_freq(), "current"):
  File "/opt/local/Library/Frameworks/Python.framework/Versions/3.9/lib/python3.9/site-packages/psutil/__init__.py", line 1869, in cpu_freq
    ret = _psplatform.cpu_freq()
  File "/opt/local/Library/Frameworks/Python.framework/Versions/3.9/lib/python3.9/site-packages/psutil/_psosx.py", line 179, in cpu_freq
    curr, min_, max_ = cext.cpu_freq()
FileNotFoundError: [Errno 2] No such file or directory (originated from sysctl(HW_CPU_FREQ))
08/10/23 (00:55:07) | ERROR: Exception while getting cpu frequency!
08/10/23 (00:55:07) | ERROR: [Errno 2] No such file or directory (originated from sysctl(HW_CPU_FREQ))
Traceback (most recent call last):
  File "/opt/local/bin/bpytop", line 3080, in _collect
    if CONFIG.show_cpu_freq and hasattr(psutil.cpu_freq(), "current"):
  File "/opt/local/Library/Frameworks/Python.framework/Versions/3.9/lib/python3.9/site-packages/psutil/__init__.py", line 1869, in cpu_freq
    ret = _psplatform.cpu_freq()
  File "/opt/local/Library/Frameworks/Python.framework/Versions/3.9/lib/python3.9/site-packages/psutil/_psosx.py", line 179, in cpu_freq
    curr, min_, max_ = cext.cpu_freq()
FileNotFoundError: [Errno 2] No such file or directory (originated from sysctl(HW_CPU_FREQ))
                                                                                                                                                                                                                                                                                                                                                                                                                              09/10/23 (21:18:30) | ERROR: Exception while getting cpu frequency!
09/10/23 (21:18:30) | ERROR: [Errno 2] No such file or directory (originated from sysctl(HW_CPU_FREQ))
Traceback (most recent call last):
  File "/opt/local/bin/bpytop", line 3080, in _collect
    if CONFIG.show_cpu_freq and hasattr(psutil.cpu_freq(), "current"):
  File "/opt/local/Library/Frameworks/Python.framework/Versions/3.9/lib/python3.9/site-packages/psutil/__init__.py", line 1869, in cpu_freq
    ret = _psplatform.cpu_freq()
  File "/opt/local/Library/Frameworks/Python.framework/Versions/3.9/lib/python3.9/site-packages/psutil/_psosx.py", line 179, in cpu_freq
    curr, min_, max_ = cext.cpu_freq()
FileNotFoundError: [Errno 2] No such file or directory (originated from sysctl(HW_CPU_FREQ))
09/10/23 (21:27:50) | ERROR: Exception while getting cpu frequency!
09/10/23 (21:27:50) | ERROR: [Errno 2] No such file or directory (originated from sysctl(HW_CPU_FREQ))
Traceback (most recent call last):
  File "/opt/local/bin/bpytop", line 3080, in _collect
    if CONFIG.show_cpu_freq and hasattr(psutil.cpu_freq(), "current"):
  File "/opt/local/Library/Frameworks/Python.framework/Versions/3.9/lib/python3.9/site-packages/psutil/__init__.py", line 1869, in cpu_freq
    ret = _psplatform.cpu_freq()
  File "/opt/local/Library/Frameworks/Python.framework/Versions/3.9/lib/python3.9/site-packages/psutil/_psosx.py", line 179, in cpu_freq
    curr, min_, max_ = cext.cpu_freq()
FileNotFoundError: [Errno 2] No such file or directory (originated from sysctl(HW_CPU_FREQ))
10/10/23 (12:29:04) | ERROR: Exception while getting cpu frequency!
10/10/23 (12:29:04) | ERROR: [Errno 2] No such file or directory (originated from sysctl(HW_CPU_FREQ))
Traceback (most recent call last):
  File "/opt/local/bin/bpytop", line 3080, in _collect
    if CONFIG.show_cpu_freq and hasattr(psutil.cpu_freq(), "current"):
  File "/opt/local/Library/Frameworks/Python.framework/Versions/3.9/lib/python3.9/site-packages/psutil/__init__.py", line 1869, in cpu_freq
    ret = _psplatform.cpu_freq()
  File "/opt/local/Library/Frameworks/Python.framework/Versions/3.9/lib/python3.9/site-packages/psutil/_psosx.py", line 179, in cpu_freq
    curr, min_, max_ = cext.cpu_freq()
FileNotFoundError: [Errno 2] No such file or directory (originated from sysctl(HW_CPU_FREQ))
21/10/23 (03:36:45) | ERROR: Exception while getting cpu frequency!
21/10/23 (03:36:45) | ERROR: [Errno 2] No such file or directory (originated from sysctl(HW_CPU_FREQ))
Traceback (most recent call last):
  File "/opt/local/bin/bpytop", line 3080, in _collect
    if CONFIG.show_cpu_freq and hasattr(psutil.cpu_freq(), "current"):
  File "/opt/local/Library/Frameworks/Python.framework/Versions/3.9/lib/python3.9/site-packages/psutil/__init__.py", line 1869, in cpu_freq
    ret = _psplatform.cpu_freq()
  File "/opt/local/Library/Frameworks/Python.framework/Versions/3.9/lib/python3.9/site-packages/psutil/_psosx.py", line 179, in cpu_freq
    curr, min_, max_ = cext.cpu_freq()
FileNotFoundError: [Errno 2] No such file or directory (originated from sysctl(HW_CPU_FREQ))
21/10/23 (13:43:08) | ERROR: Exception while getting cpu frequency!
21/10/23 (13:43:08) | ERROR: [Errno 2] No such file or directory (originated from sysctl(HW_CPU_FREQ))
Traceback (most recent call last):
  File "/opt/local/bin/bpytop", line 3080, in _collect
    if CONFIG.show_cpu_freq and hasattr(psutil.cpu_freq(), "current"):
  File "/opt/local/Library/Frameworks/Python.framework/Versions/3.9/lib/python3.9/site-packages/psutil/__init__.py", line 1869, in cpu_freq
    ret = _psplatform.cpu_freq()
  File "/opt/local/Library/Frameworks/Python.framework/Versions/3.9/lib/python3.9/site-packages/psutil/_psosx.py", line 179, in cpu_freq
    curr, min_, max_ = cext.cpu_freq()
FileNotFoundError: [Errno 2] No such file or directory (originated from sysctl(HW_CPU_FREQ))
22/10/23 (05:09:58) | ERROR: Exception while getting cpu frequency!
22/10/23 (05:09:58) | ERROR: [Errno 2] No such file or directory (originated from sysctl(HW_CPU_FREQ))
Traceback (most recent call last):
  File "/opt/local/bin/bpytop", line 3080, in _collect
    if CONFIG.show_cpu_freq and hasattr(psutil.cpu_freq(), "current"):
  File "/opt/local/Library/Frameworks/Python.framework/Versions/3.9/lib/python3.9/site-packages/psutil/__init__.py", line 1869, in cpu_freq
    ret = _psplatform.cpu_freq()
  File "/opt/local/Library/Frameworks/Python.framework/Versions/3.9/lib/python3.9/site-packages/psutil/_psosx.py", line 179, in cpu_freq
    curr, min_, max_ = cext.cpu_freq()
FileNotFoundError: [Errno 2] No such file or directory (originated from sysctl(HW_CPU_FREQ))
22/10/23 (05:23:06) | ERROR: Exception while getting cpu frequency!
22/10/23 (05:23:06) | ERROR: [Errno 2] No such file or directory (originated from sysctl(HW_CPU_FREQ))
Traceback (most recent call last):
  File "/opt/local/bin/bpytop", line 3080, in _collect
    if CONFIG.show_cpu_freq and hasattr(psutil.cpu_freq(), "current"):
  File "/opt/local/Library/Frameworks/Python.framework/Versions/3.9/lib/python3.9/site-packages/psutil/__init__.py", line 1869, in cpu_freq
    ret = _psplatform.cpu_freq()
  File "/opt/local/Library/Frameworks/Python.framework/Versions/3.9/lib/python3.9/site-packages/psutil/_psosx.py", line 179, in cpu_freq
    curr, min_, max_ = cext.cpu_freq()
FileNotFoundError: [Errno 2] No such file or directory (originated from sysctl(HW_CPU_FREQ))
23/10/23 (00:16:47) | ERROR: Exception while getting cpu frequency!
23/10/23 (00:16:47) | ERROR: [Errno 2] No such file or directory (originated from sysctl(HW_CPU_FREQ))
Traceback (most recent call last):
  File "/opt/local/bin/bpytop", line 3080, in _collect
    if CONFIG.show_cpu_freq and hasattr(psutil.cpu_freq(), "current"):
  File "/opt/local/Library/Frameworks/Python.framework/Versions/3.9/lib/python3.9/site-packages/psutil/__init__.py", line 1869, in cpu_freq
    ret = _psplatform.cpu_freq()
  File "/opt/local/Library/Frameworks/Python.framework/Versions/3.9/lib/python3.9/site-packages/psutil/_psosx.py", line 179, in cpu_freq
    curr, min_, max_ = cext.cpu_freq()
FileNotFoundError: [Errno 2] No such file or directory (originated from sysctl(HW_CPU_FREQ))
26/10/23 (03:17:56) | ERROR: Exception while getting cpu frequency!
26/10/23 (03:17:56) | ERROR: [Errno 2] No such file or directory (originated from sysctl(HW_CPU_FREQ))
Traceback (most recent call last):
  File "/opt/local/bin/bpytop", line 3080, in _collect
    if CONFIG.show_cpu_freq and hasattr(psutil.cpu_freq(), "current"):
  File "/opt/local/Library/Frameworks/Python.framework/Versions/3.9/lib/python3.9/site-packages/psutil/__init__.py", line 1869, in cpu_freq
    ret = _psplatform.cpu_freq()
  File "/opt/local/Library/Frameworks/Python.framework/Versions/3.9/lib/python3.9/site-packages/psutil/_psosx.py", line 179, in cpu_freq
    curr, min_, max_ = cext.cpu_freq()
FileNotFoundError: [Errno 2] No such file or directory (originated from sysctl(HW_CPU_FREQ))
28/10/23 (03:35:38) | ERROR: Exception while getting cpu frequency!
28/10/23 (03:35:38) | ERROR: [Errno 2] No such file or directory (originated from sysctl(HW_CPU_FREQ))
Traceback (most recent call last):
  File "/opt/local/bin/bpytop", line 3080, in _collect
    if CONFIG.show_cpu_freq and hasattr(psutil.cpu_freq(), "current"):
  File "/opt/local/Library/Frameworks/Python.framework/Versions/3.9/lib/python3.9/site-packages/psutil/__init__.py", line 1869, in cpu_freq
    ret = _psplatform.cpu_freq()
  File "/opt/local/Library/Frameworks/Python.framework/Versions/3.9/lib/python3.9/site-packages/psutil/_psosx.py", line 179, in cpu_freq
    curr, min_, max_ = cext.cpu_freq()
FileNotFoundError: [Errno 2] No such file or directory (originated from sysctl(HW_CPU_FREQ))
13/12/23 (13:00:44) | ERROR: Exception while getting cpu frequency!
13/12/23 (13:00:44) | ERROR: [Errno 2] No such file or directory (originated from sysctl(HW_CPU_FREQ))
Traceback (most recent call last):
  File "/opt/local/bin/bpytop", line 3080, in _collect
    if CONFIG.show_cpu_freq and hasattr(psutil.cpu_freq(), "current"):
  File "/Users/larseberhart/Library/Python/3.9/lib/python/site-packages/psutil/__init__.py", line 1872, in cpu_freq
    ret = _psplatform.cpu_freq()
  File "/Users/larseberhart/Library/Python/3.9/lib/python/site-packages/psutil/_psosx.py", line 179, in cpu_freq
    curr, min_, max_ = cext.cpu_freq()
FileNotFoundError: [Errno 2] No such file or directory (originated from sysctl(HW_CPU_FREQ))
13/01/24 (23:00:14) | ERROR: Exception while getting cpu frequency!
13/01/24 (23:00:14) | ERROR: [Errno 2] No such file or directory (originated from sysctl(HW_CPU_FREQ))
Traceback (most recent call last):
  File "/opt/local/bin/bpytop", line 3080, in _collect
    if CONFIG.show_cpu_freq and hasattr(psutil.cpu_freq(), "current"):
  File "/Users/larseberhart/Library/Python/3.9/lib/python/site-packages/psutil/__init__.py", line 1872, in cpu_freq
    ret = _psplatform.cpu_freq()
  File "/Users/larseberhart/Library/Python/3.9/lib/python/site-packages/psutil/_psosx.py", line 179, in cpu_freq
    curr, min_, max_ = cext.cpu_freq()
FileNotFoundError: [Errno 2] No such file or directory (originated from sysctl(HW_CPU_FREQ))
13/01/24 (23:25:40) | ERROR: Data collection thread failed with exception: [Errno 5] Input/output error
Traceback (most recent call last):
  File "/opt/local/bin/bpytop", line 2945, in _runner
    if CONFIG.draw_clock and CONFIG.update_ms != 1000: Box.draw_clock()
  File "/opt/local/bin/bpytop", line 1746, in draw_clock
    Draw.buffer("clock", out, z=1, now=now, once=not force, only_save=Menu.active)
  File "/opt/local/bin/bpytop", line 1066, in buffer
    cls.out(name)
  File "/opt/local/bin/bpytop", line 1080, in out
    cls.now(out)
  File "/opt/local/bin/bpytop", line 1039, in now
    print(*args, sep="", end="", flush=True)
OSError: [Errno 5] Input/output error
19/01/24 (16:50:53) | ERROR: Exception while getting cpu frequency!
19/01/24 (16:50:53) | ERROR: [Errno 2] No such file or directory (originated from sysctl(HW_CPU_FREQ))
Traceback (most recent call last):
  File "/opt/local/bin/bpytop", line 3080, in _collect
    if CONFIG.show_cpu_freq and hasattr(psutil.cpu_freq(), "current"):
  File "/Users/larseberhart/Library/Python/3.9/lib/python/site-packages/psutil/__init__.py", line 1872, in cpu_freq
    ret = _psplatform.cpu_freq()
  File "/Users/larseberhart/Library/Python/3.9/lib/python/site-packages/psutil/_psosx.py", line 179, in cpu_freq
    curr, min_, max_ = cext.cpu_freq()
FileNotFoundError: [Errno 2] No such file or directory (originated from sysctl(HW_CPU_FREQ))
20/01/24 (15:22:29) | ERROR: Exception while getting cpu frequency!
20/01/24 (15:22:29) | ERROR: [Errno 2] No such file or directory (originated from sysctl(HW_CPU_FREQ))
Traceback (most recent call last):
  File "/opt/local/bin/bpytop", line 3080, in _collect
    if CONFIG.show_cpu_freq and hasattr(psutil.cpu_freq(), "current"):
                                        ^^^^^^^^^^^^^^^^^
  File "/opt/local/Library/Frameworks/Python.framework/Versions/3.12/lib/python3.12/site-packages/psutil/__init__.py", line 1876, in cpu_freq
    ret = _psplatform.cpu_freq()
          ^^^^^^^^^^^^^^^^^^^^^^
  File "/opt/local/Library/Frameworks/Python.framework/Versions/3.12/lib/python3.12/site-packages/psutil/_psosx.py", line 179, in cpu_freq
    curr, min_, max_ = cext.cpu_freq()
                       ^^^^^^^^^^^^^^^
FileNotFoundError: [Errno 2] No such file or directory (originated from sysctl(HW_CPU_FREQ))
21/01/24 (15:44:15) | ERROR: <urlopen error [Errno 8] nodename nor servname provided, or not known>
Traceback (most recent call last):
  File "/opt/local/Library/Frameworks/Python.framework/Versions/3.12/lib/python3.12/urllib/request.py", line 1344, in do_open
    h.request(req.get_method(), req.selector, req.data, headers,
  File "/opt/local/Library/Frameworks/Python.framework/Versions/3.12/lib/python3.12/http/client.py", line 1327, in request
    self._send_request(method, url, body, headers, encode_chunked)
  File "/opt/local/Library/Frameworks/Python.framework/Versions/3.12/lib/python3.12/http/client.py", line 1373, in _send_request
    self.endheaders(body, encode_chunked=encode_chunked)
  File "/opt/local/Library/Frameworks/Python.framework/Versions/3.12/lib/python3.12/http/client.py", line 1322, in endheaders
    self._send_output(message_body, encode_chunked=encode_chunked)
  File "/opt/local/Library/Frameworks/Python.framework/Versions/3.12/lib/python3.12/http/client.py", line 1081, in _send_output
    self.send(msg)
  File "/opt/local/Library/Frameworks/Python.framework/Versions/3.12/lib/python3.12/http/client.py", line 1025, in send
    self.connect()
  File "/opt/local/Library/Frameworks/Python.framework/Versions/3.12/lib/python3.12/http/client.py", line 1461, in connect
    super().connect()
  File "/opt/local/Library/Frameworks/Python.framework/Versions/3.12/lib/python3.12/http/client.py", line 991, in connect
    self.sock = self._create_connection(
                ^^^^^^^^^^^^^^^^^^^^^^^^
  File "/opt/local/Library/Frameworks/Python.framework/Versions/3.12/lib/python3.12/socket.py", line 828, in create_connection
    for res in getaddrinfo(host, port, 0, SOCK_STREAM):
               ^^^^^^^^^^^^^^^^^^^^^^^^^^^^^^^^^^^^^^^
  File "/opt/local/Library/Frameworks/Python.framework/Versions/3.12/lib/python3.12/socket.py", line 963, in getaddrinfo
    for res in _socket.getaddrinfo(host, port, family, type, proto, flags):
               ^^^^^^^^^^^^^^^^^^^^^^^^^^^^^^^^^^^^^^^^^^^^^^^^^^^^^^^^^^^
socket.gaierror: [Errno 8] nodename nor servname provided, or not known

During handling of the above exception, another exception occurred:

Traceback (most recent call last):
  File "/opt/local/bin/bpytop", line 5029, in _checker
    with urllib.request.urlopen("https://github.com/aristocratos/bpytop/raw/master/bpytop.py", timeout=5) as source: # type: ignore
         ^^^^^^^^^^^^^^^^^^^^^^^^^^^^^^^^^^^^^^^^^^^^^^^^^^^^^^^^^^^^^^^^^^^^^^^^^^^^^^^^^^^^^^^^^^^^^^^^
  File "/opt/local/Library/Frameworks/Python.framework/Versions/3.12/lib/python3.12/urllib/request.py", line 215, in urlopen
    return opener.open(url, data, timeout)
           ^^^^^^^^^^^^^^^^^^^^^^^^^^^^^^^
  File "/opt/local/Library/Frameworks/Python.framework/Versions/3.12/lib/python3.12/urllib/request.py", line 515, in open
    response = self._open(req, data)
               ^^^^^^^^^^^^^^^^^^^^^
  File "/opt/local/Library/Frameworks/Python.framework/Versions/3.12/lib/python3.12/urllib/request.py", line 532, in _open
    result = self._call_chain(self.handle_open, protocol, protocol +
             ^^^^^^^^^^^^^^^^^^^^^^^^^^^^^^^^^^^^^^^^^^^^^^^^^^^^^^^
  File "/opt/local/Library/Frameworks/Python.framework/Versions/3.12/lib/python3.12/urllib/request.py", line 492, in _call_chain
    result = func(*args)
             ^^^^^^^^^^^
  File "/opt/local/Library/Frameworks/Python.framework/Versions/3.12/lib/python3.12/urllib/request.py", line 1392, in https_open
    return self.do_open(http.client.HTTPSConnection, req,
           ^^^^^^^^^^^^^^^^^^^^^^^^^^^^^^^^^^^^^^^^^^^^^^
  File "/opt/local/Library/Frameworks/Python.framework/Versions/3.12/lib/python3.12/urllib/request.py", line 1347, in do_open
    raise URLError(err)
urllib.error.URLError: <urlopen error [Errno 8] nodename nor servname provided, or not known>
21/01/24 (15:44:15) | ERROR: Exception while getting cpu frequency!
21/01/24 (15:44:15) | ERROR: [Errno 2] No such file or directory (originated from sysctl(HW_CPU_FREQ))
Traceback (most recent call last):
  File "/opt/local/bin/bpytop", line 3080, in _collect
    if CONFIG.show_cpu_freq and hasattr(psutil.cpu_freq(), "current"):
                                        ^^^^^^^^^^^^^^^^^
  File "/opt/local/Library/Frameworks/Python.framework/Versions/3.12/lib/python3.12/site-packages/psutil/__init__.py", line 1876, in cpu_freq
    ret = _psplatform.cpu_freq()
          ^^^^^^^^^^^^^^^^^^^^^^
  File "/opt/local/Library/Frameworks/Python.framework/Versions/3.12/lib/python3.12/site-packages/psutil/_psosx.py", line 179, in cpu_freq
    curr, min_, max_ = cext.cpu_freq()
                       ^^^^^^^^^^^^^^^
FileNotFoundError: [Errno 2] No such file or directory (originated from sysctl(HW_CPU_FREQ))
21/01/24 (20:44:40) | ERROR: Exception while getting cpu frequency!
21/01/24 (20:44:40) | ERROR: [Errno 2] No such file or directory (originated from sysctl(HW_CPU_FREQ))
Traceback (most recent call last):
  File "/opt/local/bin/bpytop", line 3080, in _collect
    if CONFIG.show_cpu_freq and hasattr(psutil.cpu_freq(), "current"):
                                        ^^^^^^^^^^^^^^^^^
  File "/opt/local/Library/Frameworks/Python.framework/Versions/3.12/lib/python3.12/site-packages/psutil/__init__.py", line 1876, in cpu_freq
    ret = _psplatform.cpu_freq()
          ^^^^^^^^^^^^^^^^^^^^^^
  File "/opt/local/Library/Frameworks/Python.framework/Versions/3.12/lib/python3.12/site-packages/psutil/_psosx.py", line 179, in cpu_freq
    curr, min_, max_ = cext.cpu_freq()
                       ^^^^^^^^^^^^^^^
FileNotFoundError: [Errno 2] No such file or directory (originated from sysctl(HW_CPU_FREQ))
21/01/24 (23:36:21) | ERROR: Exception while getting cpu frequency!
21/01/24 (23:36:21) | ERROR: [Errno 2] No such file or directory (originated from sysctl(HW_CPU_FREQ))
Traceback (most recent call last):
  File "/opt/local/bin/bpytop", line 3080, in _collect
    if CONFIG.show_cpu_freq and hasattr(psutil.cpu_freq(), "current"):
                                        ^^^^^^^^^^^^^^^^^
  File "/opt/local/Library/Frameworks/Python.framework/Versions/3.12/lib/python3.12/site-packages/psutil/__init__.py", line 1876, in cpu_freq
    ret = _psplatform.cpu_freq()
          ^^^^^^^^^^^^^^^^^^^^^^
  File "/opt/local/Library/Frameworks/Python.framework/Versions/3.12/lib/python3.12/site-packages/psutil/_psosx.py", line 179, in cpu_freq
    curr, min_, max_ = cext.cpu_freq()
                       ^^^^^^^^^^^^^^^
FileNotFoundError: [Errno 2] No such file or directory (originated from sysctl(HW_CPU_FREQ))
23/01/24 (09:22:00) | ERROR: Exception while getting cpu frequency!
23/01/24 (09:22:00) | ERROR: [Errno 2] No such file or directory (originated from sysctl(HW_CPU_FREQ))
Traceback (most recent call last):
  File "/opt/local/bin/bpytop", line 3080, in _collect
    if CONFIG.show_cpu_freq and hasattr(psutil.cpu_freq(), "current"):
                                        ^^^^^^^^^^^^^^^^^
  File "/opt/local/Library/Frameworks/Python.framework/Versions/3.12/lib/python3.12/site-packages/psutil/__init__.py", line 1876, in cpu_freq
    ret = _psplatform.cpu_freq()
          ^^^^^^^^^^^^^^^^^^^^^^
  File "/opt/local/Library/Frameworks/Python.framework/Versions/3.12/lib/python3.12/site-packages/psutil/_psosx.py", line 179, in cpu_freq
    curr, min_, max_ = cext.cpu_freq()
                       ^^^^^^^^^^^^^^^
FileNotFoundError: [Errno 2] No such file or directory (originated from sysctl(HW_CPU_FREQ))
23/01/24 (09:22:06) | ERROR: <urlopen error timed out>
Traceback (most recent call last):
  File "/opt/local/Library/Frameworks/Python.framework/Versions/3.12/lib/python3.12/urllib/request.py", line 1344, in do_open
    h.request(req.get_method(), req.selector, req.data, headers,
  File "/opt/local/Library/Frameworks/Python.framework/Versions/3.12/lib/python3.12/http/client.py", line 1327, in request
    self._send_request(method, url, body, headers, encode_chunked)
  File "/opt/local/Library/Frameworks/Python.framework/Versions/3.12/lib/python3.12/http/client.py", line 1373, in _send_request
    self.endheaders(body, encode_chunked=encode_chunked)
  File "/opt/local/Library/Frameworks/Python.framework/Versions/3.12/lib/python3.12/http/client.py", line 1322, in endheaders
    self._send_output(message_body, encode_chunked=encode_chunked)
  File "/opt/local/Library/Frameworks/Python.framework/Versions/3.12/lib/python3.12/http/client.py", line 1081, in _send_output
    self.send(msg)
  File "/opt/local/Library/Frameworks/Python.framework/Versions/3.12/lib/python3.12/http/client.py", line 1025, in send
    self.connect()
  File "/opt/local/Library/Frameworks/Python.framework/Versions/3.12/lib/python3.12/http/client.py", line 1461, in connect
    super().connect()
  File "/opt/local/Library/Frameworks/Python.framework/Versions/3.12/lib/python3.12/http/client.py", line 991, in connect
    self.sock = self._create_connection(
                ^^^^^^^^^^^^^^^^^^^^^^^^
  File "/opt/local/Library/Frameworks/Python.framework/Versions/3.12/lib/python3.12/socket.py", line 852, in create_connection
    raise exceptions[0]
  File "/opt/local/Library/Frameworks/Python.framework/Versions/3.12/lib/python3.12/socket.py", line 837, in create_connection
    sock.connect(sa)
TimeoutError: timed out

During handling of the above exception, another exception occurred:

Traceback (most recent call last):
  File "/opt/local/bin/bpytop", line 5029, in _checker
    with urllib.request.urlopen("https://github.com/aristocratos/bpytop/raw/master/bpytop.py", timeout=5) as source: # type: ignore
         ^^^^^^^^^^^^^^^^^^^^^^^^^^^^^^^^^^^^^^^^^^^^^^^^^^^^^^^^^^^^^^^^^^^^^^^^^^^^^^^^^^^^^^^^^^^^^^^^
  File "/opt/local/Library/Frameworks/Python.framework/Versions/3.12/lib/python3.12/urllib/request.py", line 215, in urlopen
    return opener.open(url, data, timeout)
           ^^^^^^^^^^^^^^^^^^^^^^^^^^^^^^^
  File "/opt/local/Library/Frameworks/Python.framework/Versions/3.12/lib/python3.12/urllib/request.py", line 515, in open
    response = self._open(req, data)
               ^^^^^^^^^^^^^^^^^^^^^
  File "/opt/local/Library/Frameworks/Python.framework/Versions/3.12/lib/python3.12/urllib/request.py", line 532, in _open
    result = self._call_chain(self.handle_open, protocol, protocol +
             ^^^^^^^^^^^^^^^^^^^^^^^^^^^^^^^^^^^^^^^^^^^^^^^^^^^^^^^
  File "/opt/local/Library/Frameworks/Python.framework/Versions/3.12/lib/python3.12/urllib/request.py", line 492, in _call_chain
    result = func(*args)
             ^^^^^^^^^^^
  File "/opt/local/Library/Frameworks/Python.framework/Versions/3.12/lib/python3.12/urllib/request.py", line 1392, in https_open
    return self.do_open(http.client.HTTPSConnection, req,
           ^^^^^^^^^^^^^^^^^^^^^^^^^^^^^^^^^^^^^^^^^^^^^^
  File "/opt/local/Library/Frameworks/Python.framework/Versions/3.12/lib/python3.12/urllib/request.py", line 1347, in do_open
    raise URLError(err)
urllib.error.URLError: <urlopen error timed out>
25/01/24 (18:04:46) | ERROR: Exception while getting cpu frequency!
25/01/24 (18:04:46) | ERROR: [Errno 2] No such file or directory (originated from sysctl(HW_CPU_FREQ))
Traceback (most recent call last):
  File "/opt/local/bin/bpytop", line 3080, in _collect
    if CONFIG.show_cpu_freq and hasattr(psutil.cpu_freq(), "current"):
                                        ^^^^^^^^^^^^^^^^^
  File "/opt/local/Library/Frameworks/Python.framework/Versions/3.12/lib/python3.12/site-packages/psutil/__init__.py", line 1876, in cpu_freq
    ret = _psplatform.cpu_freq()
          ^^^^^^^^^^^^^^^^^^^^^^
  File "/opt/local/Library/Frameworks/Python.framework/Versions/3.12/lib/python3.12/site-packages/psutil/_psosx.py", line 179, in cpu_freq
    curr, min_, max_ = cext.cpu_freq()
                       ^^^^^^^^^^^^^^^
FileNotFoundError: [Errno 2] No such file or directory (originated from sysctl(HW_CPU_FREQ))
26/01/24 (13:05:30) | ERROR: Exception while getting cpu frequency!
26/01/24 (13:05:30) | ERROR: [Errno 2] No such file or directory (originated from sysctl(HW_CPU_FREQ))
Traceback (most recent call last):
  File "/opt/local/bin/bpytop", line 3080, in _collect
    if CONFIG.show_cpu_freq and hasattr(psutil.cpu_freq(), "current"):
                                        ^^^^^^^^^^^^^^^^^
  File "/opt/local/Library/Frameworks/Python.framework/Versions/3.12/lib/python3.12/site-packages/psutil/__init__.py", line 1876, in cpu_freq
    ret = _psplatform.cpu_freq()
          ^^^^^^^^^^^^^^^^^^^^^^
  File "/opt/local/Library/Frameworks/Python.framework/Versions/3.12/lib/python3.12/site-packages/psutil/_psosx.py", line 179, in cpu_freq
    curr, min_, max_ = cext.cpu_freq()
                       ^^^^^^^^^^^^^^^
FileNotFoundError: [Errno 2] No such file or directory (originated from sysctl(HW_CPU_FREQ))
26/01/24 (13:35:43) | ERROR: Exception while getting cpu frequency!
26/01/24 (13:35:43) | ERROR: [Errno 2] No such file or directory (originated from sysctl(HW_CPU_FREQ))
Traceback (most recent call last):
  File "/opt/local/bin/bpytop", line 3080, in _collect
    if CONFIG.show_cpu_freq and hasattr(psutil.cpu_freq(), "current"):
                                        ^^^^^^^^^^^^^^^^^
  File "/opt/local/Library/Frameworks/Python.framework/Versions/3.12/lib/python3.12/site-packages/psutil/__init__.py", line 1876, in cpu_freq
    ret = _psplatform.cpu_freq()
          ^^^^^^^^^^^^^^^^^^^^^^
  File "/opt/local/Library/Frameworks/Python.framework/Versions/3.12/lib/python3.12/site-packages/psutil/_psosx.py", line 179, in cpu_freq
    curr, min_, max_ = cext.cpu_freq()
                       ^^^^^^^^^^^^^^^
FileNotFoundError: [Errno 2] No such file or directory (originated from sysctl(HW_CPU_FREQ))
27/01/24 (16:27:19) | ERROR: Exception while getting cpu frequency!
27/01/24 (16:27:19) | ERROR: [Errno 2] No such file or directory (originated from sysctl(HW_CPU_FREQ))
Traceback (most recent call last):
  File "/opt/local/bin/bpytop", line 3080, in _collect
    if CONFIG.show_cpu_freq and hasattr(psutil.cpu_freq(), "current"):
                                        ^^^^^^^^^^^^^^^^^
  File "/opt/local/Library/Frameworks/Python.framework/Versions/3.12/lib/python3.12/site-packages/psutil/__init__.py", line 1876, in cpu_freq
    ret = _psplatform.cpu_freq()
          ^^^^^^^^^^^^^^^^^^^^^^
  File "/opt/local/Library/Frameworks/Python.framework/Versions/3.12/lib/python3.12/site-packages/psutil/_psosx.py", line 179, in cpu_freq
    curr, min_, max_ = cext.cpu_freq()
                       ^^^^^^^^^^^^^^^
FileNotFoundError: [Errno 2] No such file or directory (originated from sysctl(HW_CPU_FREQ))
28/01/24 (18:47:20) | ERROR: Exception while getting cpu frequency!
28/01/24 (18:47:20) | ERROR: [Errno 2] No such file or directory (originated from sysctl(HW_CPU_FREQ))
Traceback (most recent call last):
  File "/opt/local/bin/bpytop", line 3080, in _collect
    if CONFIG.show_cpu_freq and hasattr(psutil.cpu_freq(), "current"):
                                        ^^^^^^^^^^^^^^^^^
  File "/opt/local/Library/Frameworks/Python.framework/Versions/3.12/lib/python3.12/site-packages/psutil/__init__.py", line 1876, in cpu_freq
    ret = _psplatform.cpu_freq()
          ^^^^^^^^^^^^^^^^^^^^^^
  File "/opt/local/Library/Frameworks/Python.framework/Versions/3.12/lib/python3.12/site-packages/psutil/_psosx.py", line 179, in cpu_freq
    curr, min_, max_ = cext.cpu_freq()
                       ^^^^^^^^^^^^^^^
FileNotFoundError: [Errno 2] No such file or directory (originated from sysctl(HW_CPU_FREQ))
17/02/24 (14:14:33) | ERROR: <urlopen error [Errno 8] nodename nor servname provided, or not known>
Traceback (most recent call last):
  File "/opt/local/Library/Frameworks/Python.framework/Versions/3.12/lib/python3.12/urllib/request.py", line 1344, in do_open
    h.request(req.get_method(), req.selector, req.data, headers,
  File "/opt/local/Library/Frameworks/Python.framework/Versions/3.12/lib/python3.12/http/client.py", line 1331, in request
    self._send_request(method, url, body, headers, encode_chunked)
  File "/opt/local/Library/Frameworks/Python.framework/Versions/3.12/lib/python3.12/http/client.py", line 1377, in _send_request
    self.endheaders(body, encode_chunked=encode_chunked)
  File "/opt/local/Library/Frameworks/Python.framework/Versions/3.12/lib/python3.12/http/client.py", line 1326, in endheaders
    self._send_output(message_body, encode_chunked=encode_chunked)
  File "/opt/local/Library/Frameworks/Python.framework/Versions/3.12/lib/python3.12/http/client.py", line 1085, in _send_output
    self.send(msg)
  File "/opt/local/Library/Frameworks/Python.framework/Versions/3.12/lib/python3.12/http/client.py", line 1029, in send
    self.connect()
  File "/opt/local/Library/Frameworks/Python.framework/Versions/3.12/lib/python3.12/http/client.py", line 1465, in connect
    super().connect()
  File "/opt/local/Library/Frameworks/Python.framework/Versions/3.12/lib/python3.12/http/client.py", line 995, in connect
    self.sock = self._create_connection(
                ^^^^^^^^^^^^^^^^^^^^^^^^
  File "/opt/local/Library/Frameworks/Python.framework/Versions/3.12/lib/python3.12/socket.py", line 828, in create_connection
    for res in getaddrinfo(host, port, 0, SOCK_STREAM):
               ^^^^^^^^^^^^^^^^^^^^^^^^^^^^^^^^^^^^^^^
  File "/opt/local/Library/Frameworks/Python.framework/Versions/3.12/lib/python3.12/socket.py", line 963, in getaddrinfo
    for res in _socket.getaddrinfo(host, port, family, type, proto, flags):
               ^^^^^^^^^^^^^^^^^^^^^^^^^^^^^^^^^^^^^^^^^^^^^^^^^^^^^^^^^^^
socket.gaierror: [Errno 8] nodename nor servname provided, or not known

During handling of the above exception, another exception occurred:

Traceback (most recent call last):
  File "/opt/local/bin/bpytop", line 5029, in _checker
    with urllib.request.urlopen("https://github.com/aristocratos/bpytop/raw/master/bpytop.py", timeout=5) as source: # type: ignore
         ^^^^^^^^^^^^^^^^^^^^^^^^^^^^^^^^^^^^^^^^^^^^^^^^^^^^^^^^^^^^^^^^^^^^^^^^^^^^^^^^^^^^^^^^^^^^^^^^
  File "/opt/local/Library/Frameworks/Python.framework/Versions/3.12/lib/python3.12/urllib/request.py", line 215, in urlopen
    return opener.open(url, data, timeout)
           ^^^^^^^^^^^^^^^^^^^^^^^^^^^^^^^
  File "/opt/local/Library/Frameworks/Python.framework/Versions/3.12/lib/python3.12/urllib/request.py", line 515, in open
    response = self._open(req, data)
               ^^^^^^^^^^^^^^^^^^^^^
  File "/opt/local/Library/Frameworks/Python.framework/Versions/3.12/lib/python3.12/urllib/request.py", line 532, in _open
    result = self._call_chain(self.handle_open, protocol, protocol +
             ^^^^^^^^^^^^^^^^^^^^^^^^^^^^^^^^^^^^^^^^^^^^^^^^^^^^^^^
  File "/opt/local/Library/Frameworks/Python.framework/Versions/3.12/lib/python3.12/urllib/request.py", line 492, in _call_chain
    result = func(*args)
             ^^^^^^^^^^^
  File "/opt/local/Library/Frameworks/Python.framework/Versions/3.12/lib/python3.12/urllib/request.py", line 1392, in https_open
    return self.do_open(http.client.HTTPSConnection, req,
           ^^^^^^^^^^^^^^^^^^^^^^^^^^^^^^^^^^^^^^^^^^^^^^
  File "/opt/local/Library/Frameworks/Python.framework/Versions/3.12/lib/python3.12/urllib/request.py", line 1347, in do_open
    raise URLError(err)
urllib.error.URLError: <urlopen error [Errno 8] nodename nor servname provided, or not known>
19/02/24 (09:40:23) | ERROR: <urlopen error timed out>
Traceback (most recent call last):
  File "/opt/local/Library/Frameworks/Python.framework/Versions/3.12/lib/python3.12/urllib/request.py", line 1344, in do_open
    h.request(req.get_method(), req.selector, req.data, headers,
  File "/opt/local/Library/Frameworks/Python.framework/Versions/3.12/lib/python3.12/http/client.py", line 1331, in request
    self._send_request(method, url, body, headers, encode_chunked)
  File "/opt/local/Library/Frameworks/Python.framework/Versions/3.12/lib/python3.12/http/client.py", line 1377, in _send_request
    self.endheaders(body, encode_chunked=encode_chunked)
  File "/opt/local/Library/Frameworks/Python.framework/Versions/3.12/lib/python3.12/http/client.py", line 1326, in endheaders
    self._send_output(message_body, encode_chunked=encode_chunked)
  File "/opt/local/Library/Frameworks/Python.framework/Versions/3.12/lib/python3.12/http/client.py", line 1085, in _send_output
    self.send(msg)
  File "/opt/local/Library/Frameworks/Python.framework/Versions/3.12/lib/python3.12/http/client.py", line 1029, in send
    self.connect()
  File "/opt/local/Library/Frameworks/Python.framework/Versions/3.12/lib/python3.12/http/client.py", line 1465, in connect
    super().connect()
  File "/opt/local/Library/Frameworks/Python.framework/Versions/3.12/lib/python3.12/http/client.py", line 995, in connect
    self.sock = self._create_connection(
                ^^^^^^^^^^^^^^^^^^^^^^^^
  File "/opt/local/Library/Frameworks/Python.framework/Versions/3.12/lib/python3.12/socket.py", line 852, in create_connection
    raise exceptions[0]
  File "/opt/local/Library/Frameworks/Python.framework/Versions/3.12/lib/python3.12/socket.py", line 837, in create_connection
    sock.connect(sa)
TimeoutError: timed out

During handling of the above exception, another exception occurred:

Traceback (most recent call last):
  File "/opt/local/bin/bpytop", line 5029, in _checker
    with urllib.request.urlopen("https://github.com/aristocratos/bpytop/raw/master/bpytop.py", timeout=5) as source: # type: ignore
         ^^^^^^^^^^^^^^^^^^^^^^^^^^^^^^^^^^^^^^^^^^^^^^^^^^^^^^^^^^^^^^^^^^^^^^^^^^^^^^^^^^^^^^^^^^^^^^^^
  File "/opt/local/Library/Frameworks/Python.framework/Versions/3.12/lib/python3.12/urllib/request.py", line 215, in urlopen
    return opener.open(url, data, timeout)
           ^^^^^^^^^^^^^^^^^^^^^^^^^^^^^^^
  File "/opt/local/Library/Frameworks/Python.framework/Versions/3.12/lib/python3.12/urllib/request.py", line 515, in open
    response = self._open(req, data)
               ^^^^^^^^^^^^^^^^^^^^^
  File "/opt/local/Library/Frameworks/Python.framework/Versions/3.12/lib/python3.12/urllib/request.py", line 532, in _open
    result = self._call_chain(self.handle_open, protocol, protocol +
             ^^^^^^^^^^^^^^^^^^^^^^^^^^^^^^^^^^^^^^^^^^^^^^^^^^^^^^^
  File "/opt/local/Library/Frameworks/Python.framework/Versions/3.12/lib/python3.12/urllib/request.py", line 492, in _call_chain
    result = func(*args)
             ^^^^^^^^^^^
  File "/opt/local/Library/Frameworks/Python.framework/Versions/3.12/lib/python3.12/urllib/request.py", line 1392, in https_open
    return self.do_open(http.client.HTTPSConnection, req,
           ^^^^^^^^^^^^^^^^^^^^^^^^^^^^^^^^^^^^^^^^^^^^^^
  File "/opt/local/Library/Frameworks/Python.framework/Versions/3.12/lib/python3.12/urllib/request.py", line 1347, in do_open
    raise URLError(err)
urllib.error.URLError: <urlopen error timed out>
05/04/24 (22:38:09) | ERROR: <urlopen error [Errno 8] nodename nor servname provided, or not known>
Traceback (most recent call last):
  File "/opt/local/Library/Frameworks/Python.framework/Versions/3.12/lib/python3.12/urllib/request.py", line 1344, in do_open
    h.request(req.get_method(), req.selector, req.data, headers,
  File "/opt/local/Library/Frameworks/Python.framework/Versions/3.12/lib/python3.12/http/client.py", line 1331, in request
    self._send_request(method, url, body, headers, encode_chunked)
  File "/opt/local/Library/Frameworks/Python.framework/Versions/3.12/lib/python3.12/http/client.py", line 1377, in _send_request
    self.endheaders(body, encode_chunked=encode_chunked)
  File "/opt/local/Library/Frameworks/Python.framework/Versions/3.12/lib/python3.12/http/client.py", line 1326, in endheaders
    self._send_output(message_body, encode_chunked=encode_chunked)
  File "/opt/local/Library/Frameworks/Python.framework/Versions/3.12/lib/python3.12/http/client.py", line 1085, in _send_output
    self.send(msg)
  File "/opt/local/Library/Frameworks/Python.framework/Versions/3.12/lib/python3.12/http/client.py", line 1029, in send
    self.connect()
  File "/opt/local/Library/Frameworks/Python.framework/Versions/3.12/lib/python3.12/http/client.py", line 1465, in connect
    super().connect()
  File "/opt/local/Library/Frameworks/Python.framework/Versions/3.12/lib/python3.12/http/client.py", line 995, in connect
    self.sock = self._create_connection(
                ^^^^^^^^^^^^^^^^^^^^^^^^
  File "/opt/local/Library/Frameworks/Python.framework/Versions/3.12/lib/python3.12/socket.py", line 828, in create_connection
    for res in getaddrinfo(host, port, 0, SOCK_STREAM):
               ^^^^^^^^^^^^^^^^^^^^^^^^^^^^^^^^^^^^^^^
  File "/opt/local/Library/Frameworks/Python.framework/Versions/3.12/lib/python3.12/socket.py", line 963, in getaddrinfo
    for res in _socket.getaddrinfo(host, port, family, type, proto, flags):
               ^^^^^^^^^^^^^^^^^^^^^^^^^^^^^^^^^^^^^^^^^^^^^^^^^^^^^^^^^^^
socket.gaierror: [Errno 8] nodename nor servname provided, or not known

During handling of the above exception, another exception occurred:

Traceback (most recent call last):
  File "/opt/local/bin/bpytop", line 5029, in _checker
    with urllib.request.urlopen("https://github.com/aristocratos/bpytop/raw/master/bpytop.py", timeout=5) as source: # type: ignore
         ^^^^^^^^^^^^^^^^^^^^^^^^^^^^^^^^^^^^^^^^^^^^^^^^^^^^^^^^^^^^^^^^^^^^^^^^^^^^^^^^^^^^^^^^^^^^^^^^
  File "/opt/local/Library/Frameworks/Python.framework/Versions/3.12/lib/python3.12/urllib/request.py", line 215, in urlopen
    return opener.open(url, data, timeout)
           ^^^^^^^^^^^^^^^^^^^^^^^^^^^^^^^
  File "/opt/local/Library/Frameworks/Python.framework/Versions/3.12/lib/python3.12/urllib/request.py", line 515, in open
    response = self._open(req, data)
               ^^^^^^^^^^^^^^^^^^^^^
  File "/opt/local/Library/Frameworks/Python.framework/Versions/3.12/lib/python3.12/urllib/request.py", line 532, in _open
    result = self._call_chain(self.handle_open, protocol, protocol +
             ^^^^^^^^^^^^^^^^^^^^^^^^^^^^^^^^^^^^^^^^^^^^^^^^^^^^^^^
  File "/opt/local/Library/Frameworks/Python.framework/Versions/3.12/lib/python3.12/urllib/request.py", line 492, in _call_chain
    result = func(*args)
             ^^^^^^^^^^^
  File "/opt/local/Library/Frameworks/Python.framework/Versions/3.12/lib/python3.12/urllib/request.py", line 1392, in https_open
    return self.do_open(http.client.HTTPSConnection, req,
           ^^^^^^^^^^^^^^^^^^^^^^^^^^^^^^^^^^^^^^^^^^^^^^
  File "/opt/local/Library/Frameworks/Python.framework/Versions/3.12/lib/python3.12/urllib/request.py", line 1347, in do_open
    raise URLError(err)
urllib.error.URLError: <urlopen error [Errno 8] nodename nor servname provided, or not known>
09/04/24 (23:34:26) | ERROR: <urlopen error [Errno 8] nodename nor servname provided, or not known>
Traceback (most recent call last):
  File "/opt/local/Library/Frameworks/Python.framework/Versions/3.12/lib/python3.12/urllib/request.py", line 1344, in do_open
    h.request(req.get_method(), req.selector, req.data, headers,
  File "/opt/local/Library/Frameworks/Python.framework/Versions/3.12/lib/python3.12/http/client.py", line 1331, in request
    self._send_request(method, url, body, headers, encode_chunked)
  File "/opt/local/Library/Frameworks/Python.framework/Versions/3.12/lib/python3.12/http/client.py", line 1377, in _send_request
    self.endheaders(body, encode_chunked=encode_chunked)
  File "/opt/local/Library/Frameworks/Python.framework/Versions/3.12/lib/python3.12/http/client.py", line 1326, in endheaders
    self._send_output(message_body, encode_chunked=encode_chunked)
  File "/opt/local/Library/Frameworks/Python.framework/Versions/3.12/lib/python3.12/http/client.py", line 1085, in _send_output
    self.send(msg)
  File "/opt/local/Library/Frameworks/Python.framework/Versions/3.12/lib/python3.12/http/client.py", line 1029, in send
    self.connect()
  File "/opt/local/Library/Frameworks/Python.framework/Versions/3.12/lib/python3.12/http/client.py", line 1465, in connect
    super().connect()
  File "/opt/local/Library/Frameworks/Python.framework/Versions/3.12/lib/python3.12/http/client.py", line 995, in connect
    self.sock = self._create_connection(
                ^^^^^^^^^^^^^^^^^^^^^^^^
  File "/opt/local/Library/Frameworks/Python.framework/Versions/3.12/lib/python3.12/socket.py", line 828, in create_connection
    for res in getaddrinfo(host, port, 0, SOCK_STREAM):
               ^^^^^^^^^^^^^^^^^^^^^^^^^^^^^^^^^^^^^^^
  File "/opt/local/Library/Frameworks/Python.framework/Versions/3.12/lib/python3.12/socket.py", line 963, in getaddrinfo
    for res in _socket.getaddrinfo(host, port, family, type, proto, flags):
               ^^^^^^^^^^^^^^^^^^^^^^^^^^^^^^^^^^^^^^^^^^^^^^^^^^^^^^^^^^^
socket.gaierror: [Errno 8] nodename nor servname provided, or not known

During handling of the above exception, another exception occurred:

Traceback (most recent call last):
  File "/opt/local/bin/bpytop", line 5029, in _checker
    with urllib.request.urlopen("https://github.com/aristocratos/bpytop/raw/master/bpytop.py", timeout=5) as source: # type: ignore
         ^^^^^^^^^^^^^^^^^^^^^^^^^^^^^^^^^^^^^^^^^^^^^^^^^^^^^^^^^^^^^^^^^^^^^^^^^^^^^^^^^^^^^^^^^^^^^^^^
  File "/opt/local/Library/Frameworks/Python.framework/Versions/3.12/lib/python3.12/urllib/request.py", line 215, in urlopen
    return opener.open(url, data, timeout)
           ^^^^^^^^^^^^^^^^^^^^^^^^^^^^^^^
  File "/opt/local/Library/Frameworks/Python.framework/Versions/3.12/lib/python3.12/urllib/request.py", line 515, in open
    response = self._open(req, data)
               ^^^^^^^^^^^^^^^^^^^^^
  File "/opt/local/Library/Frameworks/Python.framework/Versions/3.12/lib/python3.12/urllib/request.py", line 532, in _open
    result = self._call_chain(self.handle_open, protocol, protocol +
             ^^^^^^^^^^^^^^^^^^^^^^^^^^^^^^^^^^^^^^^^^^^^^^^^^^^^^^^
  File "/opt/local/Library/Frameworks/Python.framework/Versions/3.12/lib/python3.12/urllib/request.py", line 492, in _call_chain
    result = func(*args)
             ^^^^^^^^^^^
  File "/opt/local/Library/Frameworks/Python.framework/Versions/3.12/lib/python3.12/urllib/request.py", line 1392, in https_open
    return self.do_open(http.client.HTTPSConnection, req,
           ^^^^^^^^^^^^^^^^^^^^^^^^^^^^^^^^^^^^^^^^^^^^^^
  File "/opt/local/Library/Frameworks/Python.framework/Versions/3.12/lib/python3.12/urllib/request.py", line 1347, in do_open
    raise URLError(err)
urllib.error.URLError: <urlopen error [Errno 8] nodename nor servname provided, or not known>
05/07/24 (14:27:39) | ERROR: <urlopen error timed out>
Traceback (most recent call last):
  File "/opt/local/Library/Frameworks/Python.framework/Versions/3.12/lib/python3.12/urllib/request.py", line 1344, in do_open
    h.request(req.get_method(), req.selector, req.data, headers,
  File "/opt/local/Library/Frameworks/Python.framework/Versions/3.12/lib/python3.12/http/client.py", line 1336, in request
    self._send_request(method, url, body, headers, encode_chunked)
  File "/opt/local/Library/Frameworks/Python.framework/Versions/3.12/lib/python3.12/http/client.py", line 1382, in _send_request
    self.endheaders(body, encode_chunked=encode_chunked)
  File "/opt/local/Library/Frameworks/Python.framework/Versions/3.12/lib/python3.12/http/client.py", line 1331, in endheaders
    self._send_output(message_body, encode_chunked=encode_chunked)
  File "/opt/local/Library/Frameworks/Python.framework/Versions/3.12/lib/python3.12/http/client.py", line 1091, in _send_output
    self.send(msg)
  File "/opt/local/Library/Frameworks/Python.framework/Versions/3.12/lib/python3.12/http/client.py", line 1035, in send
    self.connect()
  File "/opt/local/Library/Frameworks/Python.framework/Versions/3.12/lib/python3.12/http/client.py", line 1470, in connect
    super().connect()
  File "/opt/local/Library/Frameworks/Python.framework/Versions/3.12/lib/python3.12/http/client.py", line 1001, in connect
    self.sock = self._create_connection(
                ^^^^^^^^^^^^^^^^^^^^^^^^
  File "/opt/local/Library/Frameworks/Python.framework/Versions/3.12/lib/python3.12/socket.py", line 853, in create_connection
    raise exceptions[0]
  File "/opt/local/Library/Frameworks/Python.framework/Versions/3.12/lib/python3.12/socket.py", line 838, in create_connection
    sock.connect(sa)
TimeoutError: timed out

During handling of the above exception, another exception occurred:

Traceback (most recent call last):
  File "/opt/local/bin/bpytop", line 5029, in _checker
    with urllib.request.urlopen("https://github.com/aristocratos/bpytop/raw/master/bpytop.py", timeout=5) as source: # type: ignore
         ^^^^^^^^^^^^^^^^^^^^^^^^^^^^^^^^^^^^^^^^^^^^^^^^^^^^^^^^^^^^^^^^^^^^^^^^^^^^^^^^^^^^^^^^^^^^^^^^
  File "/opt/local/Library/Frameworks/Python.framework/Versions/3.12/lib/python3.12/urllib/request.py", line 215, in urlopen
    return opener.open(url, data, timeout)
           ^^^^^^^^^^^^^^^^^^^^^^^^^^^^^^^
  File "/opt/local/Library/Frameworks/Python.framework/Versions/3.12/lib/python3.12/urllib/request.py", line 515, in open
    response = self._open(req, data)
               ^^^^^^^^^^^^^^^^^^^^^
  File "/opt/local/Library/Frameworks/Python.framework/Versions/3.12/lib/python3.12/urllib/request.py", line 532, in _open
    result = self._call_chain(self.handle_open, protocol, protocol +
             ^^^^^^^^^^^^^^^^^^^^^^^^^^^^^^^^^^^^^^^^^^^^^^^^^^^^^^^
  File "/opt/local/Library/Frameworks/Python.framework/Versions/3.12/lib/python3.12/urllib/request.py", line 492, in _call_chain
    result = func(*args)
             ^^^^^^^^^^^
  File "/opt/local/Library/Frameworks/Python.framework/Versions/3.12/lib/python3.12/urllib/request.py", line 1392, in https_open
    return self.do_open(http.client.HTTPSConnection, req,
           ^^^^^^^^^^^^^^^^^^^^^^^^^^^^^^^^^^^^^^^^^^^^^^
  File "/opt/local/Library/Frameworks/Python.framework/Versions/3.12/lib/python3.12/urllib/request.py", line 1347, in do_open
    raise URLError(err)
urllib.error.URLError: <urlopen error timed out>
20/08/24 (09:02:40) | ERROR: <urlopen error [SSL: CERTIFICATE_VERIFY_FAILED] certificate verify failed: unable to get local issuer certificate (_ssl.c:1000)>
Traceback (most recent call last):
  File "/opt/local/Library/Frameworks/Python.framework/Versions/3.12/lib/python3.12/urllib/request.py", line 1344, in do_open
    h.request(req.get_method(), req.selector, req.data, headers,
  File "/opt/local/Library/Frameworks/Python.framework/Versions/3.12/lib/python3.12/http/client.py", line 1336, in request
    self._send_request(method, url, body, headers, encode_chunked)
  File "/opt/local/Library/Frameworks/Python.framework/Versions/3.12/lib/python3.12/http/client.py", line 1382, in _send_request
    self.endheaders(body, encode_chunked=encode_chunked)
  File "/opt/local/Library/Frameworks/Python.framework/Versions/3.12/lib/python3.12/http/client.py", line 1331, in endheaders
    self._send_output(message_body, encode_chunked=encode_chunked)
  File "/opt/local/Library/Frameworks/Python.framework/Versions/3.12/lib/python3.12/http/client.py", line 1091, in _send_output
    self.send(msg)
  File "/opt/local/Library/Frameworks/Python.framework/Versions/3.12/lib/python3.12/http/client.py", line 1035, in send
    self.connect()
  File "/opt/local/Library/Frameworks/Python.framework/Versions/3.12/lib/python3.12/http/client.py", line 1477, in connect
    self.sock = self._context.wrap_socket(self.sock,
                ^^^^^^^^^^^^^^^^^^^^^^^^^^^^^^^^^^^^
  File "/opt/local/Library/Frameworks/Python.framework/Versions/3.12/lib/python3.12/ssl.py", line 455, in wrap_socket
    return self.sslsocket_class._create(
           ^^^^^^^^^^^^^^^^^^^^^^^^^^^^^
  File "/opt/local/Library/Frameworks/Python.framework/Versions/3.12/lib/python3.12/ssl.py", line 1042, in _create
    self.do_handshake()
  File "/opt/local/Library/Frameworks/Python.framework/Versions/3.12/lib/python3.12/ssl.py", line 1320, in do_handshake
    self._sslobj.do_handshake()
ssl.SSLCertVerificationError: [SSL: CERTIFICATE_VERIFY_FAILED] certificate verify failed: unable to get local issuer certificate (_ssl.c:1000)

During handling of the above exception, another exception occurred:

Traceback (most recent call last):
  File "/opt/local/bin/bpytop", line 5029, in _checker
    with urllib.request.urlopen("https://github.com/aristocratos/bpytop/raw/master/bpytop.py", timeout=5) as source: # type: ignore
         ^^^^^^^^^^^^^^^^^^^^^^^^^^^^^^^^^^^^^^^^^^^^^^^^^^^^^^^^^^^^^^^^^^^^^^^^^^^^^^^^^^^^^^^^^^^^^^^^
  File "/opt/local/Library/Frameworks/Python.framework/Versions/3.12/lib/python3.12/urllib/request.py", line 215, in urlopen
    return opener.open(url, data, timeout)
           ^^^^^^^^^^^^^^^^^^^^^^^^^^^^^^^
  File "/opt/local/Library/Frameworks/Python.framework/Versions/3.12/lib/python3.12/urllib/request.py", line 515, in open
    response = self._open(req, data)
               ^^^^^^^^^^^^^^^^^^^^^
  File "/opt/local/Library/Frameworks/Python.framework/Versions/3.12/lib/python3.12/urllib/request.py", line 532, in _open
    result = self._call_chain(self.handle_open, protocol, protocol +
             ^^^^^^^^^^^^^^^^^^^^^^^^^^^^^^^^^^^^^^^^^^^^^^^^^^^^^^^
  File "/opt/local/Library/Frameworks/Python.framework/Versions/3.12/lib/python3.12/urllib/request.py", line 492, in _call_chain
    result = func(*args)
             ^^^^^^^^^^^
  File "/opt/local/Library/Frameworks/Python.framework/Versions/3.12/lib/python3.12/urllib/request.py", line 1392, in https_open
    return self.do_open(http.client.HTTPSConnection, req,
           ^^^^^^^^^^^^^^^^^^^^^^^^^^^^^^^^^^^^^^^^^^^^^^
  File "/opt/local/Library/Frameworks/Python.framework/Versions/3.12/lib/python3.12/urllib/request.py", line 1347, in do_open
    raise URLError(err)
urllib.error.URLError: <urlopen error [SSL: CERTIFICATE_VERIFY_FAILED] certificate verify failed: unable to get local issuer certificate (_ssl.c:1000)>
20/08/24 (09:17:29) | ERROR: <urlopen error [SSL: CERTIFICATE_VERIFY_FAILED] certificate verify failed: unable to get local issuer certificate (_ssl.c:1000)>
Traceback (most recent call last):
  File "/opt/local/Library/Frameworks/Python.framework/Versions/3.12/lib/python3.12/urllib/request.py", line 1344, in do_open
    h.request(req.get_method(), req.selector, req.data, headers,
  File "/opt/local/Library/Frameworks/Python.framework/Versions/3.12/lib/python3.12/http/client.py", line 1336, in request
    self._send_request(method, url, body, headers, encode_chunked)
  File "/opt/local/Library/Frameworks/Python.framework/Versions/3.12/lib/python3.12/http/client.py", line 1382, in _send_request
    self.endheaders(body, encode_chunked=encode_chunked)
  File "/opt/local/Library/Frameworks/Python.framework/Versions/3.12/lib/python3.12/http/client.py", line 1331, in endheaders
    self._send_output(message_body, encode_chunked=encode_chunked)
  File "/opt/local/Library/Frameworks/Python.framework/Versions/3.12/lib/python3.12/http/client.py", line 1091, in _send_output
    self.send(msg)
  File "/opt/local/Library/Frameworks/Python.framework/Versions/3.12/lib/python3.12/http/client.py", line 1035, in send
    self.connect()
  File "/opt/local/Library/Frameworks/Python.framework/Versions/3.12/lib/python3.12/http/client.py", line 1477, in connect
    self.sock = self._context.wrap_socket(self.sock,
                ^^^^^^^^^^^^^^^^^^^^^^^^^^^^^^^^^^^^
  File "/opt/local/Library/Frameworks/Python.framework/Versions/3.12/lib/python3.12/ssl.py", line 455, in wrap_socket
    return self.sslsocket_class._create(
           ^^^^^^^^^^^^^^^^^^^^^^^^^^^^^
  File "/opt/local/Library/Frameworks/Python.framework/Versions/3.12/lib/python3.12/ssl.py", line 1042, in _create
    self.do_handshake()
  File "/opt/local/Library/Frameworks/Python.framework/Versions/3.12/lib/python3.12/ssl.py", line 1320, in do_handshake
    self._sslobj.do_handshake()
ssl.SSLCertVerificationError: [SSL: CERTIFICATE_VERIFY_FAILED] certificate verify failed: unable to get local issuer certificate (_ssl.c:1000)

During handling of the above exception, another exception occurred:

Traceback (most recent call last):
  File "/opt/local/bin/bpytop", line 5029, in _checker
    with urllib.request.urlopen("https://github.com/aristocratos/bpytop/raw/master/bpytop.py", timeout=5) as source: # type: ignore
         ^^^^^^^^^^^^^^^^^^^^^^^^^^^^^^^^^^^^^^^^^^^^^^^^^^^^^^^^^^^^^^^^^^^^^^^^^^^^^^^^^^^^^^^^^^^^^^^^
  File "/opt/local/Library/Frameworks/Python.framework/Versions/3.12/lib/python3.12/urllib/request.py", line 215, in urlopen
    return opener.open(url, data, timeout)
           ^^^^^^^^^^^^^^^^^^^^^^^^^^^^^^^
  File "/opt/local/Library/Frameworks/Python.framework/Versions/3.12/lib/python3.12/urllib/request.py", line 515, in open
    response = self._open(req, data)
               ^^^^^^^^^^^^^^^^^^^^^
  File "/opt/local/Library/Frameworks/Python.framework/Versions/3.12/lib/python3.12/urllib/request.py", line 532, in _open
    result = self._call_chain(self.handle_open, protocol, protocol +
             ^^^^^^^^^^^^^^^^^^^^^^^^^^^^^^^^^^^^^^^^^^^^^^^^^^^^^^^
  File "/opt/local/Library/Frameworks/Python.framework/Versions/3.12/lib/python3.12/urllib/request.py", line 492, in _call_chain
    result = func(*args)
             ^^^^^^^^^^^
  File "/opt/local/Library/Frameworks/Python.framework/Versions/3.12/lib/python3.12/urllib/request.py", line 1392, in https_open
    return self.do_open(http.client.HTTPSConnection, req,
           ^^^^^^^^^^^^^^^^^^^^^^^^^^^^^^^^^^^^^^^^^^^^^^
  File "/opt/local/Library/Frameworks/Python.framework/Versions/3.12/lib/python3.12/urllib/request.py", line 1347, in do_open
    raise URLError(err)
urllib.error.URLError: <urlopen error [SSL: CERTIFICATE_VERIFY_FAILED] certificate verify failed: unable to get local issuer certificate (_ssl.c:1000)>
22/08/24 (12:34:54) | ERROR: <urlopen error [SSL: CERTIFICATE_VERIFY_FAILED] certificate verify failed: unable to get local issuer certificate (_ssl.c:1000)>
Traceback (most recent call last):
  File "/opt/local/Library/Frameworks/Python.framework/Versions/3.12/lib/python3.12/urllib/request.py", line 1344, in do_open
    h.request(req.get_method(), req.selector, req.data, headers,
  File "/opt/local/Library/Frameworks/Python.framework/Versions/3.12/lib/python3.12/http/client.py", line 1336, in request
    self._send_request(method, url, body, headers, encode_chunked)
  File "/opt/local/Library/Frameworks/Python.framework/Versions/3.12/lib/python3.12/http/client.py", line 1382, in _send_request
    self.endheaders(body, encode_chunked=encode_chunked)
  File "/opt/local/Library/Frameworks/Python.framework/Versions/3.12/lib/python3.12/http/client.py", line 1331, in endheaders
    self._send_output(message_body, encode_chunked=encode_chunked)
  File "/opt/local/Library/Frameworks/Python.framework/Versions/3.12/lib/python3.12/http/client.py", line 1091, in _send_output
    self.send(msg)
  File "/opt/local/Library/Frameworks/Python.framework/Versions/3.12/lib/python3.12/http/client.py", line 1035, in send
    self.connect()
  File "/opt/local/Library/Frameworks/Python.framework/Versions/3.12/lib/python3.12/http/client.py", line 1477, in connect
    self.sock = self._context.wrap_socket(self.sock,
                ^^^^^^^^^^^^^^^^^^^^^^^^^^^^^^^^^^^^
  File "/opt/local/Library/Frameworks/Python.framework/Versions/3.12/lib/python3.12/ssl.py", line 455, in wrap_socket
    return self.sslsocket_class._create(
           ^^^^^^^^^^^^^^^^^^^^^^^^^^^^^
  File "/opt/local/Library/Frameworks/Python.framework/Versions/3.12/lib/python3.12/ssl.py", line 1042, in _create
    self.do_handshake()
  File "/opt/local/Library/Frameworks/Python.framework/Versions/3.12/lib/python3.12/ssl.py", line 1320, in do_handshake
    self._sslobj.do_handshake()
ssl.SSLCertVerificationError: [SSL: CERTIFICATE_VERIFY_FAILED] certificate verify failed: unable to get local issuer certificate (_ssl.c:1000)

During handling of the above exception, another exception occurred:

Traceback (most recent call last):
  File "/opt/local/bin/bpytop", line 5029, in _checker
    with urllib.request.urlopen("https://github.com/aristocratos/bpytop/raw/master/bpytop.py", timeout=5) as source: # type: ignore
         ^^^^^^^^^^^^^^^^^^^^^^^^^^^^^^^^^^^^^^^^^^^^^^^^^^^^^^^^^^^^^^^^^^^^^^^^^^^^^^^^^^^^^^^^^^^^^^^^
  File "/opt/local/Library/Frameworks/Python.framework/Versions/3.12/lib/python3.12/urllib/request.py", line 215, in urlopen
    return opener.open(url, data, timeout)
           ^^^^^^^^^^^^^^^^^^^^^^^^^^^^^^^
  File "/opt/local/Library/Frameworks/Python.framework/Versions/3.12/lib/python3.12/urllib/request.py", line 515, in open
    response = self._open(req, data)
               ^^^^^^^^^^^^^^^^^^^^^
  File "/opt/local/Library/Frameworks/Python.framework/Versions/3.12/lib/python3.12/urllib/request.py", line 532, in _open
    result = self._call_chain(self.handle_open, protocol, protocol +
             ^^^^^^^^^^^^^^^^^^^^^^^^^^^^^^^^^^^^^^^^^^^^^^^^^^^^^^^
  File "/opt/local/Library/Frameworks/Python.framework/Versions/3.12/lib/python3.12/urllib/request.py", line 492, in _call_chain
    result = func(*args)
             ^^^^^^^^^^^
  File "/opt/local/Library/Frameworks/Python.framework/Versions/3.12/lib/python3.12/urllib/request.py", line 1392, in https_open
    return self.do_open(http.client.HTTPSConnection, req,
           ^^^^^^^^^^^^^^^^^^^^^^^^^^^^^^^^^^^^^^^^^^^^^^
  File "/opt/local/Library/Frameworks/Python.framework/Versions/3.12/lib/python3.12/urllib/request.py", line 1347, in do_open
    raise URLError(err)
urllib.error.URLError: <urlopen error [SSL: CERTIFICATE_VERIFY_FAILED] certificate verify failed: unable to get local issuer certificate (_ssl.c:1000)>
                                                                                                                                                                                                                                                                                                                                           12/11/24 (01:01:11) | ERROR: <urlopen error timed out>
Traceback (most recent call last):
  File "/opt/homebrew/Cellar/python@3.13/3.13.0_1/Frameworks/Python.framework/Versions/3.13/lib/python3.13/urllib/request.py", line 1319, in do_open
    h.request(req.get_method(), req.selector, req.data, headers,
    ~~~~~~~~~^^^^^^^^^^^^^^^^^^^^^^^^^^^^^^^^^^^^^^^^^^^^^^^^^^^
              encode_chunked=req.has_header('Transfer-encoding'))
              ^^^^^^^^^^^^^^^^^^^^^^^^^^^^^^^^^^^^^^^^^^^^^^^^^^^
  File "/opt/homebrew/Cellar/python@3.13/3.13.0_1/Frameworks/Python.framework/Versions/3.13/lib/python3.13/http/client.py", line 1336, in request
    self._send_request(method, url, body, headers, encode_chunked)
    ~~~~~~~~~~~~~~~~~~^^^^^^^^^^^^^^^^^^^^^^^^^^^^^^^^^^^^^^^^^^^^
  File "/opt/homebrew/Cellar/python@3.13/3.13.0_1/Frameworks/Python.framework/Versions/3.13/lib/python3.13/http/client.py", line 1382, in _send_request
    self.endheaders(body, encode_chunked=encode_chunked)
    ~~~~~~~~~~~~~~~^^^^^^^^^^^^^^^^^^^^^^^^^^^^^^^^^^^^^
  File "/opt/homebrew/Cellar/python@3.13/3.13.0_1/Frameworks/Python.framework/Versions/3.13/lib/python3.13/http/client.py", line 1331, in endheaders
    self._send_output(message_body, encode_chunked=encode_chunked)
    ~~~~~~~~~~~~~~~~~^^^^^^^^^^^^^^^^^^^^^^^^^^^^^^^^^^^^^^^^^^^^^
  File "/opt/homebrew/Cellar/python@3.13/3.13.0_1/Frameworks/Python.framework/Versions/3.13/lib/python3.13/http/client.py", line 1091, in _send_output
    self.send(msg)
    ~~~~~~~~~^^^^^
  File "/opt/homebrew/Cellar/python@3.13/3.13.0_1/Frameworks/Python.framework/Versions/3.13/lib/python3.13/http/client.py", line 1035, in send
    self.connect()
    ~~~~~~~~~~~~^^
  File "/opt/homebrew/Cellar/python@3.13/3.13.0_1/Frameworks/Python.framework/Versions/3.13/lib/python3.13/http/client.py", line 1470, in connect
    super().connect()
    ~~~~~~~~~~~~~~~^^
  File "/opt/homebrew/Cellar/python@3.13/3.13.0_1/Frameworks/Python.framework/Versions/3.13/lib/python3.13/http/client.py", line 1001, in connect
    self.sock = self._create_connection(
                ~~~~~~~~~~~~~~~~~~~~~~~^
        (self.host,self.port), self.timeout, self.source_address)
        ^^^^^^^^^^^^^^^^^^^^^^^^^^^^^^^^^^^^^^^^^^^^^^^^^^^^^^^^^
  File "/opt/homebrew/Cellar/python@3.13/3.13.0_1/Frameworks/Python.framework/Versions/3.13/lib/python3.13/socket.py", line 864, in create_connection
    raise exceptions[0]
  File "/opt/homebrew/Cellar/python@3.13/3.13.0_1/Frameworks/Python.framework/Versions/3.13/lib/python3.13/socket.py", line 849, in create_connection
    sock.connect(sa)
    ~~~~~~~~~~~~^^^^
TimeoutError: timed out

During handling of the above exception, another exception occurred:

Traceback (most recent call last):
  File "/opt/homebrew/bin/bpytop", line 5029, in _checker
    with urllib.request.urlopen("https://github.com/aristocratos/bpytop/raw/master/bpytop.py", timeout=5) as source: # type: ignore
         ~~~~~~~~~~~~~~~~~~~~~~^^^^^^^^^^^^^^^^^^^^^^^^^^^^^^^^^^^^^^^^^^^^^^^^^^^^^^^^^^^^^^^^^^^^^^^^^^
  File "/opt/homebrew/Cellar/python@3.13/3.13.0_1/Frameworks/Python.framework/Versions/3.13/lib/python3.13/urllib/request.py", line 189, in urlopen
    return opener.open(url, data, timeout)
           ~~~~~~~~~~~^^^^^^^^^^^^^^^^^^^^
  File "/opt/homebrew/Cellar/python@3.13/3.13.0_1/Frameworks/Python.framework/Versions/3.13/lib/python3.13/urllib/request.py", line 489, in open
    response = self._open(req, data)
  File "/opt/homebrew/Cellar/python@3.13/3.13.0_1/Frameworks/Python.framework/Versions/3.13/lib/python3.13/urllib/request.py", line 506, in _open
    result = self._call_chain(self.handle_open, protocol, protocol +
                              '_open', req)
  File "/opt/homebrew/Cellar/python@3.13/3.13.0_1/Frameworks/Python.framework/Versions/3.13/lib/python3.13/urllib/request.py", line 466, in _call_chain
    result = func(*args)
  File "/opt/homebrew/Cellar/python@3.13/3.13.0_1/Frameworks/Python.framework/Versions/3.13/lib/python3.13/urllib/request.py", line 1367, in https_open
    return self.do_open(http.client.HTTPSConnection, req,
           ~~~~~~~~~~~~^^^^^^^^^^^^^^^^^^^^^^^^^^^^^^^^^^
                        context=self._context)
                        ^^^^^^^^^^^^^^^^^^^^^^
  File "/opt/homebrew/Cellar/python@3.13/3.13.0_1/Frameworks/Python.framework/Versions/3.13/lib/python3.13/urllib/request.py", line 1322, in do_open
    raise URLError(err)
urllib.error.URLError: <urlopen error timed out>
